Workbook

Sheet README
B1: Global LNG Liquefaction (Export) Capacity by Terminal by Year
B2: Nameplate capacity in Mtpa · 2010–2025
B4: WHAT THIS IS
B5: Year-by-year nameplate liquefaction (LNG export) capacity for every operational export terminal worldwide, from 2010 to 2025. "Nameplate" = design/rated capacity in million tonnes per annum (Mtpa).
B7: SOURCE
B8: IGU (International Gas Union) World LNG Report 2026 — Appendix 1: "Table of Global Liquefaction Plants, end-2025" (train-level nameplate capacity, start year, technology, ownership).
B9: GIIGNL 2026 Annual Report — used for cross-validation. It reports global liquefaction capacity of 524 MTPA across 24 exporting countries at end-2025, consistent with the IGU total of 524.6 Mtpa used here.
B11: SHEETS
B12: • Terminal x Year — one row per export terminal; columns 2010–2025 show operational nameplate capacity as of each year-end. THE MAIN DELIVERABLE.
B13: • Country x Year — the same series aggregated to the 26 exporting countries.
B14: • Train detail — the underlying train-by-train records (country, plant, train, technology, start year, capacity, ownership). All year figures are SUMIFS formulas over this sheet.
B15: • Under construction — IGU Appendix 2 (plants sanctioned / under construction, end-2025). Reference only; NOT included in the 2010–2025 series.
... B27: Built 2026-07-31 from user-provided reports. Global end-2025 total: 524.6 Mtpa across 55 terminals / 26 countries / 180 trains.

Sheet Monthly outages (Mtpa)
A1: TIME | D1: Algeria | H1: Angola | I1: Australia | S1: Brunei | T1: Cameroon | U1: Canada | V1: China | W1: Congo | Y1: Egypt | AA1: Equatorial Guinea | AB1: Indonesia | AE1: Malaysia | AH1: Mauritania | AI1: Mexico | AK1: Mozambique | AL1: Nigeria | AM1: Norway | AO1: Oman | AP1: Papua New Guinea | AQ1: Peru | AR1: Qatar | AS1: Russia | AX1: Trinidad and Tobago | AY1: UAE | AZ1: United States | BI1: Yemen
A2: Month | B2: MonthKey | C2: Total offline | D2: Arzew GL1Z | E2: Arzew GL2Z | F2: Arzew GL3Z (Gassi Touil) | G2: Skikda GL1K | H2: Angola LNG | I2: Australia Pacific LNG | J2: Darwin LNG | K2: GLNG | L2: Gorgon LNG | M2: Ichthys LNG | N2: North West Shelf LNG | O2: Pluto LNG | P2: Prelude FLNG | Q2: Queensland Curtis LNG | R2: Wheatstone LNG | S2: Brunei LNG | T2: Cameroon FLNG | U2: LNG Canada | V2: Inland facilities | W2: Congo Marine XII FLNG | X2: Congo Nguya FLNG | Y2: Damietta LNG | Z2: Egyptian LNG (Idku) | AA2: EG LNG | AB2: Bontang LNG | AC2: Donggi- Senoro LNG | AD2: Tangguh LNG | AE2: MLNG | AF2: Petronas FLNG 1 Satu | AG2: Petronas FLNG 2 Rotan | AH2: Tortue/ Ahmeyim FLNG | AI2: Altamira LNG | AJ2: Energia Costa Azul (ECA) | AK2: Coral South FLNG | AL2: NLNG | AM2: Nordic LNG | AN2: Snohvit LNG | AO2: Oman LNG | AP2: PNG LNG | AQ2: Peru LNG | AR2: QatarGas LNG | AS2: Arctic LNG 2 | AT2: Portovaya LNG | AU2: Sakhalin 2 | AV2: Vysotsk LNG | AW2: Yamal LNG | AX2: Atlantic LNG | AY2: Adgas LNG | AZ2: Calcasieu Pass LNG | BA2: Cameron LNG | BB2: Corpus Christi LNG | BC2: Cove Point LNG | BD2: Elba Island LNG | BE2: Freeport LNG | BF2: Golden Pass LNG | BG2: Plaquemines LNG | BH2: Sabine Pass LNG | BI2: Yemen LNG
A3: 40179 | B3: 201001 | C3: =SUM(D3:BI3) -> 8 | D3: =SUMIFS('Outages (event ledger)'!$H$2:$H$65,'Outages (event ledger)'!$A$2:$A$65,D$2,'Outages (event ledger)'!$E$2:$E$65,"<="&$B3,'Outages (event ledger)'!$G$2:$G$65,">="&$B3) -> 0 | E3: =SUMIFS('Outages (event ledger)'!$H$2:$H$65,'Outages (event ledger)'!$A$2:$A$65,E$2,'Outages (event ledger)'!$E$2:$E$65,"<="&$B3,'Outages (event ledger)'!$G$2:$G$65,">="&$B3) -> 0 | F3: =SUMIFS('Outages (event ledger)'!$H$2:$H$65,'Outages (event ledger)'!$A$2:$A$65,F$2,'Outages (event ledger)'!$E$2:$E$65,"<="&$B3,'Outages (event ledger)'!$G$2:$G$65,">="&$B3) -> 0 | G3: =SUMIFS('Outages (event ledger)'!$H$2:$H$65,'Outages (event ledger)'!$A$2:$A$65,G$2,'Outages (event ledger)'!$E$2:$E$65,"<="&$B3,'Outages (event ledger)'!$G$2:$G$65,">="&$B3) -> 0 | H3: =SUMIFS('Outages (event ledger)'!$H$2:$H$65,'Outages (event ledger)'!$A$2:$A$65,H$2,'Outages (event ledger)'!$E$2:$E$65,"<="&$B3,'Outages (event ledger)'!$G$2:$G$65,">="&$B3) -> 0 | I3: =SUMIFS('Outages (event ledger)'!$H$2:$H$65,'Outages (event ledger)'!$A$2:$A$65,I$2,'Outages (event ledger)'!$E$2:$E$65,"<="&$B3,'Outages (event ledger)'!$G$2:$G$65,">="&$B3) -> 0 | J3: =SUMIFS('Outages (event ledger)'!$H$2:$H$65,'Outages (event ledger)'!$A$2:$A$65,J$2,'Outages (event ledger)'!$E$2:$E$65,"<="&$B3,'Outages (event ledger)'!$G$2:$G$65,">="&$B3) -> 0 | K3: =SUMIFS('Outages (event ledger)'!$H$2:$H$65,'Outages (event ledger)'!$A$2:$A$65,K$2,'Outages (event ledger)'!$E$2:$E$65,"<="&$B3,'Outages (event ledger)'!$G$2:$G$65,">="&$B3) -> 0 | ... BI3: =SUMIFS('Outages (event ledger)'!$H$2:$H$65,'Outages (event ledger)'!$A$2:$A$65,BI$2,'Outages (event ledger)'!$E$2:$E$65,"<="&$B3,'Outages (event ledger)'!$G$2:$G$65,">="&$B3) -> 0
A4: 40210 | B4: 201002 | C4: =SUM(D4:BI4) -> 8 | D4: =SUMIFS('Outages (event ledger)'!$H$2:$H$65,'Outages (event ledger)'!$A$2:$A$65,D$2,'Outages (event ledger)'!$E$2:$E$65,"<="&$B4,'Outages (event ledger)'!$G$2:$G$65,">="&$B4) -> 0 | E4: =SUMIFS('Outages (event ledger)'!$H$2:$H$65,'Outages (event ledger)'!$A$2:$A$65,E$2,'Outages (event ledger)'!$E$2:$E$65,"<="&$B4,'Outages (event ledger)'!$G$2:$G$65,">="&$B4) -> 0 | F4: =SUMIFS('Outages (event ledger)'!$H$2:$H$65,'Outages (event ledger)'!$A$2:$A$65,F$2,'Outages (event ledger)'!$E$2:$E$65,"<="&$B4,'Outages (event ledger)'!$G$2:$G$65,">="&$B4) -> 0 | G4: =SUMIFS('Outages (event ledger)'!$H$2:$H$65,'Outages (event ledger)'!$A$2:$A$65,G$2,'Outages (event ledger)'!$E$2:$E$65,"<="&$B4,'Outages (event ledger)'!$G$2:$G$65,">="&$B4) -> 0 | H4: =SUMIFS('Outages (event ledger)'!$H$2:$H$65,'Outages (event ledger)'!$A$2:$A$65,H$2,'Outages (event ledger)'!$E$2:$E$65,"<="&$B4,'Outages (event ledger)'!$G$2:$G$65,">="&$B4) -> 0 | I4: =SUMIFS('Outages (event ledger)'!$H$2:$H$65,'Outages (event ledger)'!$A$2:$A$65,I$2,'Outages (event ledger)'!$E$2:$E$65,"<="&$B4,'Outages (event ledger)'!$G$2:$G$65,">="&$B4) -> 0 | J4: =SUMIFS('Outages (event ledger)'!$H$2:$H$65,'Outages (event ledger)'!$A$2:$A$65,J$2,'Outages (event ledger)'!$E$2:$E$65,"<="&$B4,'Outages (event ledger)'!$G$2:$G$65,">="&$B4) -> 0 | K4: =SUMIFS('Outages (event ledger)'!$H$2:$H$65,'Outages (event ledger)'!$A$2:$A$65,K$2,'Outages (event ledger)'!$E$2:$E$65,"<="&$B4,'Outages (event ledger)'!$G$2:$G$65,">="&$B4) -> 0 | ... BI4: =SUMIFS('Outages (event ledger)'!$H$2:$H$65,'Outages (event ledger)'!$A$2:$A$65,BI$2,'Outages (event ledger)'!$E$2:$E$65,"<="&$B4,'Outages (event ledger)'!$G$2:$G$65,">="&$B4) -> 0
A5: 40238 | B5: 201003 | C5: =SUM(D5:BI5) -> 8 | D5: =SUMIFS('Outages (event ledger)'!$H$2:$H$65,'Outages (event ledger)'!$A$2:$A$65,D$2,'Outages (event ledger)'!$E$2:$E$65,"<="&$B5,'Outages (event ledger)'!$G$2:$G$65,">="&$B5) -> 0 | E5: =SUMIFS('Outages (event ledger)'!$H$2:$H$65,'Outages (event ledger)'!$A$2:$A$65,E$2,'Outages (event ledger)'!$E$2:$E$65,"<="&$B5,'Outages (event ledger)'!$G$2:$G$65,">="&$B5) -> 0 | F5: =SUMIFS('Outages (event ledger)'!$H$2:$H$65,'Outages (event ledger)'!$A$2:$A$65,F$2,'Outages (event ledger)'!$E$2:$E$65,"<="&$B5,'Outages (event ledger)'!$G$2:$G$65,">="&$B5) -> 0 | G5: =SUMIFS('Outages (event ledger)'!$H$2:$H$65,'Outages (event ledger)'!$A$2:$A$65,G$2,'Outages (event ledger)'!$E$2:$E$65,"<="&$B5,'Outages (event ledger)'!$G$2:$G$65,">="&$B5) -> 0 | H5: =SUMIFS('Outages (event ledger)'!$H$2:$H$65,'Outages (event ledger)'!$A$2:$A$65,H$2,'Outages (event ledger)'!$E$2:$E$65,"<="&$B5,'Outages (event ledger)'!$G$2:$G$65,">="&$B5) -> 0 | I5: =SUMIFS('Outages (event ledger)'!$H$2:$H$65,'Outages (event ledger)'!$A$2:$A$65,I$2,'Outages (event ledger)'!$E$2:$E$65,"<="&$B5,'Outages (event ledger)'!$G$2:$G$65,">="&$B5) -> 0 | J5: =SUMIFS('Outages (event ledger)'!$H$2:$H$65,'Outages (event ledger)'!$A$2:$A$65,J$2,'Outages (event ledger)'!$E$2:$E$65,"<="&$B5,'Outages (event ledger)'!$G$2:$G$65,">="&$B5) -> 0 | K5: =SUMIFS('Outages (event ledger)'!$H$2:$H$65,'Outages (event ledger)'!$A$2:$A$65,K$2,'Outages (event ledger)'!$E$2:$E$65,"<="&$B5,'Outages (event ledger)'!$G$2:$G$65,">="&$B5) -> 0 | ... BI5: =SUMIFS('Outages (event ledger)'!$H$2:$H$65,'Outages (event ledger)'!$A$2:$A$65,BI$2,'Outages (event ledger)'!$E$2:$E$65,"<="&$B5,'Outages (event ledger)'!$G$2:$G$65,">="&$B5) -> 0
A6: 40269 | B6: 201004 | C6: =SUM(D6:BI6) -> 8 | D6: =SUMIFS('Outages (event ledger)'!$H$2:$H$65,'Outages (event ledger)'!$A$2:$A$65,D$2,'Outages (event ledger)'!$E$2:$E$65,"<="&$B6,'Outages (event ledger)'!$G$2:$G$65,">="&$B6) -> 0 | E6: =SUMIFS('Outages (event ledger)'!$H$2:$H$65,'Outages (event ledger)'!$A$2:$A$65,E$2,'Outages (event ledger)'!$E$2:$E$65,"<="&$B6,'Outages (event ledger)'!$G$2:$G$65,">="&$B6) -> 0 | F6: =SUMIFS('Outages (event ledger)'!$H$2:$H$65,'Outages (event ledger)'!$A$2:$A$65,F$2,'Outages (event ledger)'!$E$2:$E$65,"<="&$B6,'Outages (event ledger)'!$G$2:$G$65,">="&$B6) -> 0 | G6: =SUMIFS('Outages (event ledger)'!$H$2:$H$65,'Outages (event ledger)'!$A$2:$A$65,G$2,'Outages (event ledger)'!$E$2:$E$65,"<="&$B6,'Outages (event ledger)'!$G$2:$G$65,">="&$B6) -> 0 | H6: =SUMIFS('Outages (event ledger)'!$H$2:$H$65,'Outages (event ledger)'!$A$2:$A$65,H$2,'Outages (event ledger)'!$E$2:$E$65,"<="&$B6,'Outages (event ledger)'!$G$2:$G$65,">="&$B6) -> 0 | I6: =SUMIFS('Outages (event ledger)'!$H$2:$H$65,'Outages (event ledger)'!$A$2:$A$65,I$2,'Outages (event ledger)'!$E$2:$E$65,"<="&$B6,'Outages (event ledger)'!$G$2:$G$65,">="&$B6) -> 0 | J6: =SUMIFS('Outages (event ledger)'!$H$2:$H$65,'Outages (event ledger)'!$A$2:$A$65,J$2,'Outages (event ledger)'!$E$2:$E$65,"<="&$B6,'Outages (event ledger)'!$G$2:$G$65,">="&$B6) -> 0 | K6: =SUMIFS('Outages (event ledger)'!$H$2:$H$65,'Outages (event ledger)'!$A$2:$A$65,K$2,'Outages (event ledger)'!$E$2:$E$65,"<="&$B6,'Outages (event ledger)'!$G$2:$G$65,">="&$B6) -> 0 | ... BI6: =SUMIFS('Outages (event ledger)'!$H$2:$H$65,'Outages (event ledger)'!$A$2:$A$65,BI$2,'Outages (event ledger)'!$E$2:$E$65,"<="&$B6,'Outages (event ledger)'!$G$2:$G$65,">="&$B6) -> 0
A7: 40299 | B7: 201005 | C7: =SUM(D7:BI7) -> 8 | D7: =SUMIFS('Outages (event ledger)'!$H$2:$H$65,'Outages (event ledger)'!$A$2:$A$65,D$2,'Outages (event ledger)'!$E$2:$E$65,"<="&$B7,'Outages (event ledger)'!$G$2:$G$65,">="&$B7) -> 0 | E7: =SUMIFS('Outages (event ledger)'!$H$2:$H$65,'Outages (event ledger)'!$A$2:$A$65,E$2,'Outages (event ledger)'!$E$2:$E$65,"<="&$B7,'Outages (event ledger)'!$G$2:$G$65,">="&$B7) -> 0 | F7: =SUMIFS('Outages (event ledger)'!$H$2:$H$65,'Outages (event ledger)'!$A$2:$A$65,F$2,'Outages (event ledger)'!$E$2:$E$65,"<="&$B7,'Outages (event ledger)'!$G$2:$G$65,">="&$B7) -> 0 | G7: =SUMIFS('Outages (event ledger)'!$H$2:$H$65,'Outages (event ledger)'!$A$2:$A$65,G$2,'Outages (event ledger)'!$E$2:$E$65,"<="&$B7,'Outages (event ledger)'!$G$2:$G$65,">="&$B7) -> 0 | H7: =SUMIFS('Outages (event ledger)'!$H$2:$H$65,'Outages (event ledger)'!$A$2:$A$65,H$2,'Outages (event ledger)'!$E$2:$E$65,"<="&$B7,'Outages (event ledger)'!$G$2:$G$65,">="&$B7) -> 0 | I7: =SUMIFS('Outages (event ledger)'!$H$2:$H$65,'Outages (event ledger)'!$A$2:$A$65,I$2,'Outages (event ledger)'!$E$2:$E$65,"<="&$B7,'Outages (event ledger)'!$G$2:$G$65,">="&$B7) -> 0 | J7: =SUMIFS('Outages (event ledger)'!$H$2:$H$65,'Outages (event ledger)'!$A$2:$A$65,J$2,'Outages (event ledger)'!$E$2:$E$65,"<="&$B7,'Outages (event ledger)'!$G$2:$G$65,">="&$B7) -> 0 | K7: =SUMIFS('Outages (event ledger)'!$H$2:$H$65,'Outages (event ledger)'!$A$2:$A$65,K$2,'Outages (event ledger)'!$E$2:$E$65,"<="&$B7,'Outages (event ledger)'!$G$2:$G$65,">="&$B7) -> 0 | ... BI7: =SUMIFS('Outages (event ledger)'!$H$2:$H$65,'Outages (event ledger)'!$A$2:$A$65,BI$2,'Outages (event ledger)'!$E$2:$E$65,"<="&$B7,'Outages (event ledger)'!$G$2:$G$65,">="&$B7) -> 0
A8: 40330 | B8: 201006 | C8: =SUM(D8:BI8) -> 8 | D8: =SUMIFS('Outages (event ledger)'!$H$2:$H$65,'Outages (event ledger)'!$A$2:$A$65,D$2,'Outages (event ledger)'!$E$2:$E$65,"<="&$B8,'Outages (event ledger)'!$G$2:$G$65,">="&$B8) -> 0 | E8: =SUMIFS('Outages (event ledger)'!$H$2:$H$65,'Outages (event ledger)'!$A$2:$A$65,E$2,'Outages (event ledger)'!$E$2:$E$65,"<="&$B8,'Outages (event ledger)'!$G$2:$G$65,">="&$B8) -> 0 | F8: =SUMIFS('Outages (event ledger)'!$H$2:$H$65,'Outages (event ledger)'!$A$2:$A$65,F$2,'Outages (event ledger)'!$E$2:$E$65,"<="&$B8,'Outages (event ledger)'!$G$2:$G$65,">="&$B8) -> 0 | G8: =SUMIFS('Outages (event ledger)'!$H$2:$H$65,'Outages (event ledger)'!$A$2:$A$65,G$2,'Outages (event ledger)'!$E$2:$E$65,"<="&$B8,'Outages (event ledger)'!$G$2:$G$65,">="&$B8) -> 0 | H8: =SUMIFS('Outages (event ledger)'!$H$2:$H$65,'Outages (event ledger)'!$A$2:$A$65,H$2,'Outages (event ledger)'!$E$2:$E$65,"<="&$B8,'Outages (event ledger)'!$G$2:$G$65,">="&$B8) -> 0 | I8: =SUMIFS('Outages (event ledger)'!$H$2:$H$65,'Outages (event ledger)'!$A$2:$A$65,I$2,'Outages (event ledger)'!$E$2:$E$65,"<="&$B8,'Outages (event ledger)'!$G$2:$G$65,">="&$B8) -> 0 | J8: =SUMIFS('Outages (event ledger)'!$H$2:$H$65,'Outages (event ledger)'!$A$2:$A$65,J$2,'Outages (event ledger)'!$E$2:$E$65,"<="&$B8,'Outages (event ledger)'!$G$2:$G$65,">="&$B8) -> 0 | K8: =SUMIFS('Outages (event ledger)'!$H$2:$H$65,'Outages (event ledger)'!$A$2:$A$65,K$2,'Outages (event ledger)'!$E$2:$E$65,"<="&$B8,'Outages (event ledger)'!$G$2:$G$65,">="&$B8) -> 0 | ... BI8: =SUMIFS('Outages (event ledger)'!$H$2:$H$65,'Outages (event ledger)'!$A$2:$A$65,BI$2,'Outages (event ledger)'!$E$2:$E$65,"<="&$B8,'Outages (event ledger)'!$G$2:$G$65,">="&$B8) -> 0
A9: 40360 | B9: 201007 | C9: =SUM(D9:BI9) -> 8 | D9: =SUMIFS('Outages (event ledger)'!$H$2:$H$65,'Outages (event ledger)'!$A$2:$A$65,D$2,'Outages (event ledger)'!$E$2:$E$65,"<="&$B9,'Outages (event ledger)'!$G$2:$G$65,">="&$B9) -> 0 | E9: =SUMIFS('Outages (event ledger)'!$H$2:$H$65,'Outages (event ledger)'!$A$2:$A$65,E$2,'Outages (event ledger)'!$E$2:$E$65,"<="&$B9,'Outages (event ledger)'!$G$2:$G$65,">="&$B9) -> 0 | F9: =SUMIFS('Outages (event ledger)'!$H$2:$H$65,'Outages (event ledger)'!$A$2:$A$65,F$2,'Outages (event ledger)'!$E$2:$E$65,"<="&$B9,'Outages (event ledger)'!$G$2:$G$65,">="&$B9) -> 0 | G9: =SUMIFS('Outages (event ledger)'!$H$2:$H$65,'Outages (event ledger)'!$A$2:$A$65,G$2,'Outages (event ledger)'!$E$2:$E$65,"<="&$B9,'Outages (event ledger)'!$G$2:$G$65,">="&$B9) -> 0 | H9: =SUMIFS('Outages (event ledger)'!$H$2:$H$65,'Outages (event ledger)'!$A$2:$A$65,H$2,'Outages (event ledger)'!$E$2:$E$65,"<="&$B9,'Outages (event ledger)'!$G$2:$G$65,">="&$B9) -> 0 | I9: =SUMIFS('Outages (event ledger)'!$H$2:$H$65,'Outages (event ledger)'!$A$2:$A$65,I$2,'Outages (event ledger)'!$E$2:$E$65,"<="&$B9,'Outages (event ledger)'!$G$2:$G$65,">="&$B9) -> 0 | J9: =SUMIFS('Outages (event ledger)'!$H$2:$H$65,'Outages (event ledger)'!$A$2:$A$65,J$2,'Outages (event ledger)'!$E$2:$E$65,"<="&$B9,'Outages (event ledger)'!$G$2:$G$65,">="&$B9) -> 0 | K9: =SUMIFS('Outages (event ledger)'!$H$2:$H$65,'Outages (event ledger)'!$A$2:$A$65,K$2,'Outages (event ledger)'!$E$2:$E$65,"<="&$B9,'Outages (event ledger)'!$G$2:$G$65,">="&$B9) -> 0 | ... BI9: =SUMIFS('Outages (event ledger)'!$H$2:$H$65,'Outages (event ledger)'!$A$2:$A$65,BI$2,'Outages (event ledger)'!$E$2:$E$65,"<="&$B9,'Outages (event ledger)'!$G$2:$G$65,">="&$B9) -> 0
A10: 40391 | B10: 201008 | C10: =SUM(D10:BI10) -> 8 | D10: =SUMIFS('Outages (event ledger)'!$H$2:$H$65,'Outages (event ledger)'!$A$2:$A$65,D$2,'Outages (event ledger)'!$E$2:$E$65,"<="&$B10,'Outages (event ledger)'!$G$2:$G$65,">="&$B10) -> 0 | E10: =SUMIFS('Outages (event ledger)'!$H$2:$H$65,'Outages (event ledger)'!$A$2:$A$65,E$2,'Outages (event ledger)'!$E$2:$E$65,"<="&$B10,'Outages (event ledger)'!$G$2:$G$65,">="&$B10) -> 0 | F10: =SUMIFS('Outages (event ledger)'!$H$2:$H$65,'Outages (event ledger)'!$A$2:$A$65,F$2,'Outages (event ledger)'!$E$2:$E$65,"<="&$B10,'Outages (event ledger)'!$G$2:$G$65,">="&$B10) -> 0 | G10: =SUMIFS('Outages (event ledger)'!$H$2:$H$65,'Outages (event ledger)'!$A$2:$A$65,G$2,'Outages (event ledger)'!$E$2:$E$65,"<="&$B10,'Outages (event ledger)'!$G$2:$G$65,">="&$B10) -> 0 | H10: =SUMIFS('Outages (event ledger)'!$H$2:$H$65,'Outages (event ledger)'!$A$2:$A$65,H$2,'Outages (event ledger)'!$E$2:$E$65,"<="&$B10,'Outages (event ledger)'!$G$2:$G$65,">="&$B10) -> 0 | I10: =SUMIFS('Outages (event ledger)'!$H$2:$H$65,'Outages (event ledger)'!$A$2:$A$65,I$2,'Outages (event ledger)'!$E$2:$E$65,"<="&$B10,'Outages (event ledger)'!$G$2:$G$65,">="&$B10) -> 0 | J10: =SUMIFS('Outages (event ledger)'!$H$2:$H$65,'Outages (event ledger)'!$A$2:$A$65,J$2,'Outages (event ledger)'!$E$2:$E$65,"<="&$B10,'Outages (event ledger)'!$G$2:$G$65,">="&$B10) -> 0 | K10: =SUMIFS('Outages (event ledger)'!$H$2:$H$65,'Outages (event ledger)'!$A$2:$A$65,K$2,'Outages (event ledger)'!$E$2:$E$65,"<="&$B10,'Outages (event ledger)'!$G$2:$G$65,">="&$B10) -> 0 | ... BI10: =SUMIFS('Outages (event ledger)'!$H$2:$H$65,'Outages (event ledger)'!$A$2:$A$65,BI$2,'Outages (event ledger)'!$E$2:$E$65,"<="&$B10,'Outages (event ledger)'!$G$2:$G$65,">="&$B10) -> 0
A11: 40422 | B11: 201009 | C11: =SUM(D11:BI11) -> 8 | D11: =SUMIFS('Outages (event ledger)'!$H$2:$H$65,'Outages (event ledger)'!$A$2:$A$65,D$2,'Outages (event ledger)'!$E$2:$E$65,"<="&$B11,'Outages (event ledger)'!$G$2:$G$65,">="&$B11) -> 0 | E11: =SUMIFS('Outages (event ledger)'!$H$2:$H$65,'Outages (event ledger)'!$A$2:$A$65,E$2,'Outages (event ledger)'!$E$2:$E$65,"<="&$B11,'Outages (event ledger)'!$G$2:$G$65,">="&$B11) -> 0 | F11: =SUMIFS('Outages (event ledger)'!$H$2:$H$65,'Outages (event ledger)'!$A$2:$A$65,F$2,'Outages (event ledger)'!$E$2:$E$65,"<="&$B11,'Outages (event ledger)'!$G$2:$G$65,">="&$B11) -> 0 | G11: =SUMIFS('Outages (event ledger)'!$H$2:$H$65,'Outages (event ledger)'!$A$2:$A$65,G$2,'Outages (event ledger)'!$E$2:$E$65,"<="&$B11,'Outages (event ledger)'!$G$2:$G$65,">="&$B11) -> 0 | H11: =SUMIFS('Outages (event ledger)'!$H$2:$H$65,'Outages (event ledger)'!$A$2:$A$65,H$2,'Outages (event ledger)'!$E$2:$E$65,"<="&$B11,'Outages (event ledger)'!$G$2:$G$65,">="&$B11) -> 0 | I11: =SUMIFS('Outages (event ledger)'!$H$2:$H$65,'Outages (event ledger)'!$A$2:$A$65,I$2,'Outages (event ledger)'!$E$2:$E$65,"<="&$B11,'Outages (event ledger)'!$G$2:$G$65,">="&$B11) -> 0 | J11: =SUMIFS('Outages (event ledger)'!$H$2:$H$65,'Outages (event ledger)'!$A$2:$A$65,J$2,'Outages (event ledger)'!$E$2:$E$65,"<="&$B11,'Outages (event ledger)'!$G$2:$G$65,">="&$B11) -> 0 | K11: =SUMIFS('Outages (event ledger)'!$H$2:$H$65,'Outages (event ledger)'!$A$2:$A$65,K$2,'Outages (event ledger)'!$E$2:$E$65,"<="&$B11,'Outages (event ledger)'!$G$2:$G$65,">="&$B11) -> 0 | ... BI11: =SUMIFS('Outages (event ledger)'!$H$2:$H$65,'Outages (event ledger)'!$A$2:$A$65,BI$2,'Outages (event ledger)'!$E$2:$E$65,"<="&$B11,'Outages (event ledger)'!$G$2:$G$65,">="&$B11) -> 0
A12: 40452 | B12: 201010 | C12: =SUM(D12:BI12) -> 8 | D12: =SUMIFS('Outages (event ledger)'!$H$2:$H$65,'Outages (event ledger)'!$A$2:$A$65,D$2,'Outages (event ledger)'!$E$2:$E$65,"<="&$B12,'Outages (event ledger)'!$G$2:$G$65,">="&$B12) -> 0 | E12: =SUMIFS('Outages (event ledger)'!$H$2:$H$65,'Outages (event ledger)'!$A$2:$A$65,E$2,'Outages (event ledger)'!$E$2:$E$65,"<="&$B12,'Outages (event ledger)'!$G$2:$G$65,">="&$B12) -> 0 | F12: =SUMIFS('Outages (event ledger)'!$H$2:$H$65,'Outages (event ledger)'!$A$2:$A$65,F$2,'Outages (event ledger)'!$E$2:$E$65,"<="&$B12,'Outages (event ledger)'!$G$2:$G$65,">="&$B12) -> 0 | G12: =SUMIFS('Outages (event ledger)'!$H$2:$H$65,'Outages (event ledger)'!$A$2:$A$65,G$2,'Outages (event ledger)'!$E$2:$E$65,"<="&$B12,'Outages (event ledger)'!$G$2:$G$65,">="&$B12) -> 0 | H12: =SUMIFS('Outages (event ledger)'!$H$2:$H$65,'Outages (event ledger)'!$A$2:$A$65,H$2,'Outages (event ledger)'!$E$2:$E$65,"<="&$B12,'Outages (event ledger)'!$G$2:$G$65,">="&$B12) -> 0 | I12: =SUMIFS('Outages (event ledger)'!$H$2:$H$65,'Outages (event ledger)'!$A$2:$A$65,I$2,'Outages (event ledger)'!$E$2:$E$65,"<="&$B12,'Outages (event ledger)'!$G$2:$G$65,">="&$B12) -> 0 | J12: =SUMIFS('Outages (event ledger)'!$H$2:$H$65,'Outages (event ledger)'!$A$2:$A$65,J$2,'Outages (event ledger)'!$E$2:$E$65,"<="&$B12,'Outages (event ledger)'!$G$2:$G$65,">="&$B12) -> 0 | K12: =SUMIFS('Outages (event ledger)'!$H$2:$H$65,'Outages (event ledger)'!$A$2:$A$65,K$2,'Outages (event ledger)'!$E$2:$E$65,"<="&$B12,'Outages (event ledger)'!$G$2:$G$65,">="&$B12) -> 0 | ... BI12: =SUMIFS('Outages (event ledger)'!$H$2:$H$65,'Outages (event ledger)'!$A$2:$A$65,BI$2,'Outages (event ledger)'!$E$2:$E$65,"<="&$B12,'Outages (event ledger)'!$G$2:$G$65,">="&$B12) -> 0
A13: 40483 | B13: 201011 | C13: =SUM(D13:BI13) -> 8 | D13: =SUMIFS('Outages (event ledger)'!$H$2:$H$65,'Outages (event ledger)'!$A$2:$A$65,D$2,'Outages (event ledger)'!$E$2:$E$65,"<="&$B13,'Outages (event ledger)'!$G$2:$G$65,">="&$B13) -> 0 | E13: =SUMIFS('Outages (event ledger)'!$H$2:$H$65,'Outages (event ledger)'!$A$2:$A$65,E$2,'Outages (event ledger)'!$E$2:$E$65,"<="&$B13,'Outages (event ledger)'!$G$2:$G$65,">="&$B13) -> 0 | F13: =SUMIFS('Outages (event ledger)'!$H$2:$H$65,'Outages (event ledger)'!$A$2:$A$65,F$2,'Outages (event ledger)'!$E$2:$E$65,"<="&$B13,'Outages (event ledger)'!$G$2:$G$65,">="&$B13) -> 0 | G13: =SUMIFS('Outages (event ledger)'!$H$2:$H$65,'Outages (event ledger)'!$A$2:$A$65,G$2,'Outages (event ledger)'!$E$2:$E$65,"<="&$B13,'Outages (event ledger)'!$G$2:$G$65,">="&$B13) -> 0 | H13: =SUMIFS('Outages (event ledger)'!$H$2:$H$65,'Outages (event ledger)'!$A$2:$A$65,H$2,'Outages (event ledger)'!$E$2:$E$65,"<="&$B13,'Outages (event ledger)'!$G$2:$G$65,">="&$B13) -> 0 | I13: =SUMIFS('Outages (event ledger)'!$H$2:$H$65,'Outages (event ledger)'!$A$2:$A$65,I$2,'Outages (event ledger)'!$E$2:$E$65,"<="&$B13,'Outages (event ledger)'!$G$2:$G$65,">="&$B13) -> 0 | J13: =SUMIFS('Outages (event ledger)'!$H$2:$H$65,'Outages (event ledger)'!$A$2:$A$65,J$2,'Outages (event ledger)'!$E$2:$E$65,"<="&$B13,'Outages (event ledger)'!$G$2:$G$65,">="&$B13) -> 0 | K13: =SUMIFS('Outages (event ledger)'!$H$2:$H$65,'Outages (event ledger)'!$A$2:$A$65,K$2,'Outages (event ledger)'!$E$2:$E$65,"<="&$B13,'Outages (event ledger)'!$G$2:$G$65,">="&$B13) -> 0 | ... BI13: =SUMIFS('Outages (event ledger)'!$H$2:$H$65,'Outages (event ledger)'!$A$2:$A$65,BI$2,'Outages (event ledger)'!$E$2:$E$65,"<="&$B13,'Outages (event ledger)'!$G$2:$G$65,">="&$B13) -> 0
A14: 40513 | B14: 201012 | C14: =SUM(D14:BI14) -> 8 | D14: =SUMIFS('Outages (event ledger)'!$H$2:$H$65,'Outages (event ledger)'!$A$2:$A$65,D$2,'Outages (event ledger)'!$E$2:$E$65,"<="&$B14,'Outages (event ledger)'!$G$2:$G$65,">="&$B14) -> 0 | E14: =SUMIFS('Outages (event ledger)'!$H$2:$H$65,'Outages (event ledger)'!$A$2:$A$65,E$2,'Outages (event ledger)'!$E$2:$E$65,"<="&$B14,'Outages (event ledger)'!$G$2:$G$65,">="&$B14) -> 0 | F14: =SUMIFS('Outages (event ledger)'!$H$2:$H$65,'Outages (event ledger)'!$A$2:$A$65,F$2,'Outages (event ledger)'!$E$2:$E$65,"<="&$B14,'Outages (event ledger)'!$G$2:$G$65,">="&$B14) -> 0 | G14: =SUMIFS('Outages (event ledger)'!$H$2:$H$65,'Outages (event ledger)'!$A$2:$A$65,G$2,'Outages (event ledger)'!$E$2:$E$65,"<="&$B14,'Outages (event ledger)'!$G$2:$G$65,">="&$B14) -> 0 | H14: =SUMIFS('Outages (event ledger)'!$H$2:$H$65,'Outages (event ledger)'!$A$2:$A$65,H$2,'Outages (event ledger)'!$E$2:$E$65,"<="&$B14,'Outages (event ledger)'!$G$2:$G$65,">="&$B14) -> 0 | I14: =SUMIFS('Outages (event ledger)'!$H$2:$H$65,'Outages (event ledger)'!$A$2:$A$65,I$2,'Outages (event ledger)'!$E$2:$E$65,"<="&$B14,'Outages (event ledger)'!$G$2:$G$65,">="&$B14) -> 0 | J14: =SUMIFS('Outages (event ledger)'!$H$2:$H$65,'Outages (event ledger)'!$A$2:$A$65,J$2,'Outages (event ledger)'!$E$2:$E$65,"<="&$B14,'Outages (event ledger)'!$G$2:$G$65,">="&$B14) -> 0 | K14: =SUMIFS('Outages (event ledger)'!$H$2:$H$65,'Outages (event ledger)'!$A$2:$A$65,K$2,'Outages (event ledger)'!$E$2:$E$65,"<="&$B14,'Outages (event ledger)'!$G$2:$G$65,">="&$B14) -> 0 | ... BI14: =SUMIFS('Outages (event ledger)'!$H$2:$H$65,'Outages (event ledger)'!$A$2:$A$65,BI$2,'Outages (event ledger)'!$E$2:$E$65,"<="&$B14,'Outages (event ledger)'!$G$2:$G$65,">="&$B14) -> 0
... A206: 46357 | B206: 202612 | C206: =SUM(D206:BI206) -> 36.1 | D206: =SUMIFS('Outages (event ledger)'!$H$2:$H$65,'Outages (event ledger)'!$A$2:$A$65,D$2,'Outages (event ledger)'!$E$2:$E$65,"<="&$B206,'Outages (event ledger)'!$G$2:$G$65,">="&$B206) -> 0 | E206: =SUMIFS('Outages (event ledger)'!$H$2:$H$65,'Outages (event ledger)'!$A$2:$A$65,E$2,'Outages (event ledger)'!$E$2:$E$65,"<="&$B206,'Outages (event ledger)'!$G$2:$G$65,">="&$B206) -> 0 | F206: =SUMIFS('Outages (event ledger)'!$H$2:$H$65,'Outages (event ledger)'!$A$2:$A$65,F$2,'Outages (event ledger)'!$E$2:$E$65,"<="&$B206,'Outages (event ledger)'!$G$2:$G$65,">="&$B206) -> 0 | G206: =SUMIFS('Outages (event ledger)'!$H$2:$H$65,'Outages (event ledger)'!$A$2:$A$65,G$2,'Outages (event ledger)'!$E$2:$E$65,"<="&$B206,'Outages (event ledger)'!$G$2:$G$65,">="&$B206) -> 0 | H206: =SUMIFS('Outages (event ledger)'!$H$2:$H$65,'Outages (event ledger)'!$A$2:$A$65,H$2,'Outages (event ledger)'!$E$2:$E$65,"<="&$B206,'Outages (event ledger)'!$G$2:$G$65,">="&$B206) -> 0 | I206: =SUMIFS('Outages (event ledger)'!$H$2:$H$65,'Outages (event ledger)'!$A$2:$A$65,I$2,'Outages (event ledger)'!$E$2:$E$65,"<="&$B206,'Outages (event ledger)'!$G$2:$G$65,">="&$B206) -> 0 | J206: =SUMIFS('Outages (event ledger)'!$H$2:$H$65,'Outages (event ledger)'!$A$2:$A$65,J$2,'Outages (event ledger)'!$E$2:$E$65,"<="&$B206,'Outages (event ledger)'!$G$2:$G$65,">="&$B206) -> 0 | K206: =SUMIFS('Outages (event ledger)'!$H$2:$H$65,'Outages (event ledger)'!$A$2:$A$65,K$2,'Outages (event ledger)'!$E$2:$E$65,"<="&$B206,'Outages (event ledger)'!$G$2:$G$65,">="&$B206) -> 0 | ... BI206: =SUMIFS('Outages (event ledger)'!$H$2:$H$65,'Outages (event ledger)'!$A$2:$A$65,BI$2,'Outages (event ledger)'!$E$2:$E$65,"<="&$B206,'Outages (event ledger)'!$G$2:$G$65,">="&$B206) -> 6.7
A208: MONTHLY LNG EXPORT CAPACITY OFFLINE (Mtpa), estimated, Jan 2010 – Dec 2026. Each cell = approx nameplate OUT that month, live SUMIFS over "Outages (event ledger)". Hover shaded cells for basis; full notes/sources in ledger.
A209: HEAVILY ESTIMATED. Short trips diluted to a monthly average (peak noted); partial-train events show affected train(s) only. Order-of-magnitude, not precise.
A210: 2026 UPDATE: Ras Laffan (Qatar) — 2 trains destroyed by missile strikes ~Mar 2026 (~12.8 Mtpa), out for years (ongoing). Late-Mar 2026 WA cyclone hit Wheatstone, North West Shelf & Gorgon (mostly brief). Freeport brief May-2026 trip. Ongoing structural shut-ins (Yemen, Trinidad, Bontang, EG LNG) carried forward through 2026.
A211: COVERAGE/SCOPE: discrete unplanned events researched through ~June 2026 (report date late Jul 2026); H2-2026 will miss new events not yet known. Sanctions & planned maintenance excluded. The 2023 Gorgon/Wheatstone strikes logged ~0 (no real output loss). Filter ledger by Type to isolate event-driven vs structural/feedgas.

Sheet Monthly capacity (Mtpa)
A1: TIME | D1: Algeria | H1: Angola | I1: Australia | S1: Brunei | T1: Cameroon | U1: Canada | V1: China | W1: Congo | Y1: Egypt | AA1: Equatorial Guinea | AB1: Indonesia | AE1: Malaysia | AH1: Mauritania | AI1: Mexico | AK1: Mozambique | AL1: Nigeria | AM1: Norway | AO1: Oman | AP1: Papua New Guinea | AQ1: Peru | AR1: Qatar | AS1: Russia | AX1: Trinidad and Tobago | AY1: UAE | AZ1: United States | BI1: Yemen
A2: Month | B2: MonthKey | C2: Global Total | D2: Arzew GL1Z | E2: Arzew GL2Z | F2: Arzew GL3Z (Gassi Touil) | G2: Skikda GL1K | H2: Angola LNG | I2: Australia Pacific LNG | J2: Darwin LNG | K2: GLNG | L2: Gorgon LNG | M2: Ichthys LNG | N2: North West Shelf LNG | O2: Pluto LNG | P2: Prelude FLNG | Q2: Queensland Curtis LNG | R2: Wheatstone LNG | S2: Brunei LNG | T2: Cameroon FLNG | U2: LNG Canada | V2: Inland facilities | W2: Congo Marine XII FLNG | X2: Congo Nguya FLNG | Y2: Damietta LNG | Z2: Egyptian LNG (Idku) | AA2: EG LNG | AB2: Bontang LNG | AC2: Donggi- Senoro LNG | AD2: Tangguh LNG | AE2: MLNG | AF2: Petronas FLNG 1 Satu | AG2: Petronas FLNG 2 Rotan | AH2: Tortue/ Ahmeyim FLNG | AI2: Altamira LNG | AJ2: Energia Costa Azul (ECA) | AK2: Coral South FLNG | AL2: NLNG | AM2: Nordic LNG | AN2: Snohvit LNG | AO2: Oman LNG | AP2: PNG LNG | AQ2: Peru LNG | AR2: QatarGas LNG | AS2: Arctic LNG 2 | AT2: Portovaya LNG | AU2: Sakhalin 2 | AV2: Vysotsk LNG | AW2: Yamal LNG | AX2: Atlantic LNG | AY2: Adgas LNG | AZ2: Calcasieu Pass LNG | BA2: Cameron LNG | BB2: Corpus Christi LNG | BC2: Cove Point LNG | BD2: Elba Island LNG | BE2: Freeport LNG | BF2: Golden Pass LNG | BG2: Plaquemines LNG | BH2: Sabine Pass LNG | BI2: Yemen LNG
A3: 40179 | B3: 201001 | C3: =SUMIFS('Additions (monthly)'!$E$2:$E$106,'Additions (monthly)'!$B$2:$B$106,"<="&$B3) -> 243.22 | D3: =SUMIFS('Additions (monthly)'!$E$2:$E$106,'Additions (monthly)'!$D$2:$D$106,D$2,'Additions (monthly)'!$B$2:$B$106,"<="&$B3) -> 7.9 | E3: =SUMIFS('Additions (monthly)'!$E$2:$E$106,'Additions (monthly)'!$D$2:$D$106,E$2,'Additions (monthly)'!$B$2:$B$106,"<="&$B3) -> 8.4 | F3: =SUMIFS('Additions (monthly)'!$E$2:$E$106,'Additions (monthly)'!$D$2:$D$106,F$2,'Additions (monthly)'!$B$2:$B$106,"<="&$B3) -> 0 | G3: =SUMIFS('Additions (monthly)'!$E$2:$E$106,'Additions (monthly)'!$D$2:$D$106,G$2,'Additions (monthly)'!$B$2:$B$106,"<="&$B3) -> 0 | H3: =SUMIFS('Additions (monthly)'!$E$2:$E$106,'Additions (monthly)'!$D$2:$D$106,H$2,'Additions (monthly)'!$B$2:$B$106,"<="&$B3) -> 0 | I3: =SUMIFS('Additions (monthly)'!$E$2:$E$106,'Additions (monthly)'!$D$2:$D$106,I$2,'Additions (monthly)'!$B$2:$B$106,"<="&$B3) -> 0 | J3: =SUMIFS('Additions (monthly)'!$E$2:$E$106,'Additions (monthly)'!$D$2:$D$106,J$2,'Additions (monthly)'!$B$2:$B$106,"<="&$B3) -> 3.7 | K3: =SUMIFS('Additions (monthly)'!$E$2:$E$106,'Additions (monthly)'!$D$2:$D$106,K$2,'Additions (monthly)'!$B$2:$B$106,"<="&$B3) -> 0 | ... BI3: =SUMIFS('Additions (monthly)'!$E$2:$E$106,'Additions (monthly)'!$D$2:$D$106,BI$2,'Additions (monthly)'!$B$2:$B$106,"<="&$B3) -> 6.7
A4: 40210 | B4: 201002 | C4: =SUMIFS('Additions (monthly)'!$E$2:$E$106,'Additions (monthly)'!$B$2:$B$106,"<="&$B4) -> 243.22 | D4: =SUMIFS('Additions (monthly)'!$E$2:$E$106,'Additions (monthly)'!$D$2:$D$106,D$2,'Additions (monthly)'!$B$2:$B$106,"<="&$B4) -> 7.9 | E4: =SUMIFS('Additions (monthly)'!$E$2:$E$106,'Additions (monthly)'!$D$2:$D$106,E$2,'Additions (monthly)'!$B$2:$B$106,"<="&$B4) -> 8.4 | F4: =SUMIFS('Additions (monthly)'!$E$2:$E$106,'Additions (monthly)'!$D$2:$D$106,F$2,'Additions (monthly)'!$B$2:$B$106,"<="&$B4) -> 0 | G4: =SUMIFS('Additions (monthly)'!$E$2:$E$106,'Additions (monthly)'!$D$2:$D$106,G$2,'Additions (monthly)'!$B$2:$B$106,"<="&$B4) -> 0 | H4: =SUMIFS('Additions (monthly)'!$E$2:$E$106,'Additions (monthly)'!$D$2:$D$106,H$2,'Additions (monthly)'!$B$2:$B$106,"<="&$B4) -> 0 | I4: =SUMIFS('Additions (monthly)'!$E$2:$E$106,'Additions (monthly)'!$D$2:$D$106,I$2,'Additions (monthly)'!$B$2:$B$106,"<="&$B4) -> 0 | J4: =SUMIFS('Additions (monthly)'!$E$2:$E$106,'Additions (monthly)'!$D$2:$D$106,J$2,'Additions (monthly)'!$B$2:$B$106,"<="&$B4) -> 3.7 | K4: =SUMIFS('Additions (monthly)'!$E$2:$E$106,'Additions (monthly)'!$D$2:$D$106,K$2,'Additions (monthly)'!$B$2:$B$106,"<="&$B4) -> 0 | ... BI4: =SUMIFS('Additions (monthly)'!$E$2:$E$106,'Additions (monthly)'!$D$2:$D$106,BI$2,'Additions (monthly)'!$B$2:$B$106,"<="&$B4) -> 6.7
A5: 40238 | B5: 201003 | C5: =SUMIFS('Additions (monthly)'!$E$2:$E$106,'Additions (monthly)'!$B$2:$B$106,"<="&$B5) -> 243.22 | D5: =SUMIFS('Additions (monthly)'!$E$2:$E$106,'Additions (monthly)'!$D$2:$D$106,D$2,'Additions (monthly)'!$B$2:$B$106,"<="&$B5) -> 7.9 | E5: =SUMIFS('Additions (monthly)'!$E$2:$E$106,'Additions (monthly)'!$D$2:$D$106,E$2,'Additions (monthly)'!$B$2:$B$106,"<="&$B5) -> 8.4 | F5: =SUMIFS('Additions (monthly)'!$E$2:$E$106,'Additions (monthly)'!$D$2:$D$106,F$2,'Additions (monthly)'!$B$2:$B$106,"<="&$B5) -> 0 | G5: =SUMIFS('Additions (monthly)'!$E$2:$E$106,'Additions (monthly)'!$D$2:$D$106,G$2,'Additions (monthly)'!$B$2:$B$106,"<="&$B5) -> 0 | H5: =SUMIFS('Additions (monthly)'!$E$2:$E$106,'Additions (monthly)'!$D$2:$D$106,H$2,'Additions (monthly)'!$B$2:$B$106,"<="&$B5) -> 0 | I5: =SUMIFS('Additions (monthly)'!$E$2:$E$106,'Additions (monthly)'!$D$2:$D$106,I$2,'Additions (monthly)'!$B$2:$B$106,"<="&$B5) -> 0 | J5: =SUMIFS('Additions (monthly)'!$E$2:$E$106,'Additions (monthly)'!$D$2:$D$106,J$2,'Additions (monthly)'!$B$2:$B$106,"<="&$B5) -> 3.7 | K5: =SUMIFS('Additions (monthly)'!$E$2:$E$106,'Additions (monthly)'!$D$2:$D$106,K$2,'Additions (monthly)'!$B$2:$B$106,"<="&$B5) -> 0 | ... BI5: =SUMIFS('Additions (monthly)'!$E$2:$E$106,'Additions (monthly)'!$D$2:$D$106,BI$2,'Additions (monthly)'!$B$2:$B$106,"<="&$B5) -> 6.7
A6: 40269 | B6: 201004 | C6: =SUMIFS('Additions (monthly)'!$E$2:$E$106,'Additions (monthly)'!$B$2:$B$106,"<="&$B6) -> 243.22 | D6: =SUMIFS('Additions (monthly)'!$E$2:$E$106,'Additions (monthly)'!$D$2:$D$106,D$2,'Additions (monthly)'!$B$2:$B$106,"<="&$B6) -> 7.9 | E6: =SUMIFS('Additions (monthly)'!$E$2:$E$106,'Additions (monthly)'!$D$2:$D$106,E$2,'Additions (monthly)'!$B$2:$B$106,"<="&$B6) -> 8.4 | F6: =SUMIFS('Additions (monthly)'!$E$2:$E$106,'Additions (monthly)'!$D$2:$D$106,F$2,'Additions (monthly)'!$B$2:$B$106,"<="&$B6) -> 0 | G6: =SUMIFS('Additions (monthly)'!$E$2:$E$106,'Additions (monthly)'!$D$2:$D$106,G$2,'Additions (monthly)'!$B$2:$B$106,"<="&$B6) -> 0 | H6: =SUMIFS('Additions (monthly)'!$E$2:$E$106,'Additions (monthly)'!$D$2:$D$106,H$2,'Additions (monthly)'!$B$2:$B$106,"<="&$B6) -> 0 | I6: =SUMIFS('Additions (monthly)'!$E$2:$E$106,'Additions (monthly)'!$D$2:$D$106,I$2,'Additions (monthly)'!$B$2:$B$106,"<="&$B6) -> 0 | J6: =SUMIFS('Additions (monthly)'!$E$2:$E$106,'Additions (monthly)'!$D$2:$D$106,J$2,'Additions (monthly)'!$B$2:$B$106,"<="&$B6) -> 3.7 | K6: =SUMIFS('Additions (monthly)'!$E$2:$E$106,'Additions (monthly)'!$D$2:$D$106,K$2,'Additions (monthly)'!$B$2:$B$106,"<="&$B6) -> 0 | ... BI6: =SUMIFS('Additions (monthly)'!$E$2:$E$106,'Additions (monthly)'!$D$2:$D$106,BI$2,'Additions (monthly)'!$B$2:$B$106,"<="&$B6) -> 6.7
A7: 40299 | B7: 201005 | C7: =SUMIFS('Additions (monthly)'!$E$2:$E$106,'Additions (monthly)'!$B$2:$B$106,"<="&$B7) -> 243.22 | D7: =SUMIFS('Additions (monthly)'!$E$2:$E$106,'Additions (monthly)'!$D$2:$D$106,D$2,'Additions (monthly)'!$B$2:$B$106,"<="&$B7) -> 7.9 | E7: =SUMIFS('Additions (monthly)'!$E$2:$E$106,'Additions (monthly)'!$D$2:$D$106,E$2,'Additions (monthly)'!$B$2:$B$106,"<="&$B7) -> 8.4 | F7: =SUMIFS('Additions (monthly)'!$E$2:$E$106,'Additions (monthly)'!$D$2:$D$106,F$2,'Additions (monthly)'!$B$2:$B$106,"<="&$B7) -> 0 | G7: =SUMIFS('Additions (monthly)'!$E$2:$E$106,'Additions (monthly)'!$D$2:$D$106,G$2,'Additions (monthly)'!$B$2:$B$106,"<="&$B7) -> 0 | H7: =SUMIFS('Additions (monthly)'!$E$2:$E$106,'Additions (monthly)'!$D$2:$D$106,H$2,'Additions (monthly)'!$B$2:$B$106,"<="&$B7) -> 0 | I7: =SUMIFS('Additions (monthly)'!$E$2:$E$106,'Additions (monthly)'!$D$2:$D$106,I$2,'Additions (monthly)'!$B$2:$B$106,"<="&$B7) -> 0 | J7: =SUMIFS('Additions (monthly)'!$E$2:$E$106,'Additions (monthly)'!$D$2:$D$106,J$2,'Additions (monthly)'!$B$2:$B$106,"<="&$B7) -> 3.7 | K7: =SUMIFS('Additions (monthly)'!$E$2:$E$106,'Additions (monthly)'!$D$2:$D$106,K$2,'Additions (monthly)'!$B$2:$B$106,"<="&$B7) -> 0 | ... BI7: =SUMIFS('Additions (monthly)'!$E$2:$E$106,'Additions (monthly)'!$D$2:$D$106,BI$2,'Additions (monthly)'!$B$2:$B$106,"<="&$B7) -> 6.7
A8: 40330 | B8: 201006 | C8: =SUMIFS('Additions (monthly)'!$E$2:$E$106,'Additions (monthly)'!$B$2:$B$106,"<="&$B8) -> 247.67 | D8: =SUMIFS('Additions (monthly)'!$E$2:$E$106,'Additions (monthly)'!$D$2:$D$106,D$2,'Additions (monthly)'!$B$2:$B$106,"<="&$B8) -> 7.9 | E8: =SUMIFS('Additions (monthly)'!$E$2:$E$106,'Additions (monthly)'!$D$2:$D$106,E$2,'Additions (monthly)'!$B$2:$B$106,"<="&$B8) -> 8.4 | F8: =SUMIFS('Additions (monthly)'!$E$2:$E$106,'Additions (monthly)'!$D$2:$D$106,F$2,'Additions (monthly)'!$B$2:$B$106,"<="&$B8) -> 0 | G8: =SUMIFS('Additions (monthly)'!$E$2:$E$106,'Additions (monthly)'!$D$2:$D$106,G$2,'Additions (monthly)'!$B$2:$B$106,"<="&$B8) -> 0 | H8: =SUMIFS('Additions (monthly)'!$E$2:$E$106,'Additions (monthly)'!$D$2:$D$106,H$2,'Additions (monthly)'!$B$2:$B$106,"<="&$B8) -> 0 | I8: =SUMIFS('Additions (monthly)'!$E$2:$E$106,'Additions (monthly)'!$D$2:$D$106,I$2,'Additions (monthly)'!$B$2:$B$106,"<="&$B8) -> 0 | J8: =SUMIFS('Additions (monthly)'!$E$2:$E$106,'Additions (monthly)'!$D$2:$D$106,J$2,'Additions (monthly)'!$B$2:$B$106,"<="&$B8) -> 3.7 | K8: =SUMIFS('Additions (monthly)'!$E$2:$E$106,'Additions (monthly)'!$D$2:$D$106,K$2,'Additions (monthly)'!$B$2:$B$106,"<="&$B8) -> 0 | ... BI8: =SUMIFS('Additions (monthly)'!$E$2:$E$106,'Additions (monthly)'!$D$2:$D$106,BI$2,'Additions (monthly)'!$B$2:$B$106,"<="&$B8) -> 6.7
A9: 40360 | B9: 201007 | C9: =SUMIFS('Additions (monthly)'!$E$2:$E$106,'Additions (monthly)'!$B$2:$B$106,"<="&$B9) -> 247.67 | D9: =SUMIFS('Additions (monthly)'!$E$2:$E$106,'Additions (monthly)'!$D$2:$D$106,D$2,'Additions (monthly)'!$B$2:$B$106,"<="&$B9) -> 7.9 | E9: =SUMIFS('Additions (monthly)'!$E$2:$E$106,'Additions (monthly)'!$D$2:$D$106,E$2,'Additions (monthly)'!$B$2:$B$106,"<="&$B9) -> 8.4 | F9: =SUMIFS('Additions (monthly)'!$E$2:$E$106,'Additions (monthly)'!$D$2:$D$106,F$2,'Additions (monthly)'!$B$2:$B$106,"<="&$B9) -> 0 | G9: =SUMIFS('Additions (monthly)'!$E$2:$E$106,'Additions (monthly)'!$D$2:$D$106,G$2,'Additions (monthly)'!$B$2:$B$106,"<="&$B9) -> 0 | H9: =SUMIFS('Additions (monthly)'!$E$2:$E$106,'Additions (monthly)'!$D$2:$D$106,H$2,'Additions (monthly)'!$B$2:$B$106,"<="&$B9) -> 0 | I9: =SUMIFS('Additions (monthly)'!$E$2:$E$106,'Additions (monthly)'!$D$2:$D$106,I$2,'Additions (monthly)'!$B$2:$B$106,"<="&$B9) -> 0 | J9: =SUMIFS('Additions (monthly)'!$E$2:$E$106,'Additions (monthly)'!$D$2:$D$106,J$2,'Additions (monthly)'!$B$2:$B$106,"<="&$B9) -> 3.7 | K9: =SUMIFS('Additions (monthly)'!$E$2:$E$106,'Additions (monthly)'!$D$2:$D$106,K$2,'Additions (monthly)'!$B$2:$B$106,"<="&$B9) -> 0 | ... BI9: =SUMIFS('Additions (monthly)'!$E$2:$E$106,'Additions (monthly)'!$D$2:$D$106,BI$2,'Additions (monthly)'!$B$2:$B$106,"<="&$B9) -> 6.7
A10: 40391 | B10: 201008 | C10: =SUMIFS('Additions (monthly)'!$E$2:$E$106,'Additions (monthly)'!$B$2:$B$106,"<="&$B10) -> 247.67 | D10: =SUMIFS('Additions (monthly)'!$E$2:$E$106,'Additions (monthly)'!$D$2:$D$106,D$2,'Additions (monthly)'!$B$2:$B$106,"<="&$B10) -> 7.9 | E10: =SUMIFS('Additions (monthly)'!$E$2:$E$106,'Additions (monthly)'!$D$2:$D$106,E$2,'Additions (monthly)'!$B$2:$B$106,"<="&$B10) -> 8.4 | F10: =SUMIFS('Additions (monthly)'!$E$2:$E$106,'Additions (monthly)'!$D$2:$D$106,F$2,'Additions (monthly)'!$B$2:$B$106,"<="&$B10) -> 0 | G10: =SUMIFS('Additions (monthly)'!$E$2:$E$106,'Additions (monthly)'!$D$2:$D$106,G$2,'Additions (monthly)'!$B$2:$B$106,"<="&$B10) -> 0 | H10: =SUMIFS('Additions (monthly)'!$E$2:$E$106,'Additions (monthly)'!$D$2:$D$106,H$2,'Additions (monthly)'!$B$2:$B$106,"<="&$B10) -> 0 | I10: =SUMIFS('Additions (monthly)'!$E$2:$E$106,'Additions (monthly)'!$D$2:$D$106,I$2,'Additions (monthly)'!$B$2:$B$106,"<="&$B10) -> 0 | J10: =SUMIFS('Additions (monthly)'!$E$2:$E$106,'Additions (monthly)'!$D$2:$D$106,J$2,'Additions (monthly)'!$B$2:$B$106,"<="&$B10) -> 3.7 | K10: =SUMIFS('Additions (monthly)'!$E$2:$E$106,'Additions (monthly)'!$D$2:$D$106,K$2,'Additions (monthly)'!$B$2:$B$106,"<="&$B10) -> 0 | ... BI10: =SUMIFS('Additions (monthly)'!$E$2:$E$106,'Additions (monthly)'!$D$2:$D$106,BI$2,'Additions (monthly)'!$B$2:$B$106,"<="&$B10) -> 6.7
A11: 40422 | B11: 201009 | C11: =SUMIFS('Additions (monthly)'!$E$2:$E$106,'Additions (monthly)'!$B$2:$B$106,"<="&$B11) -> 247.67 | D11: =SUMIFS('Additions (monthly)'!$E$2:$E$106,'Additions (monthly)'!$D$2:$D$106,D$2,'Additions (monthly)'!$B$2:$B$106,"<="&$B11) -> 7.9 | E11: =SUMIFS('Additions (monthly)'!$E$2:$E$106,'Additions (monthly)'!$D$2:$D$106,E$2,'Additions (monthly)'!$B$2:$B$106,"<="&$B11) -> 8.4 | F11: =SUMIFS('Additions (monthly)'!$E$2:$E$106,'Additions (monthly)'!$D$2:$D$106,F$2,'Additions (monthly)'!$B$2:$B$106,"<="&$B11) -> 0 | G11: =SUMIFS('Additions (monthly)'!$E$2:$E$106,'Additions (monthly)'!$D$2:$D$106,G$2,'Additions (monthly)'!$B$2:$B$106,"<="&$B11) -> 0 | H11: =SUMIFS('Additions (monthly)'!$E$2:$E$106,'Additions (monthly)'!$D$2:$D$106,H$2,'Additions (monthly)'!$B$2:$B$106,"<="&$B11) -> 0 | I11: =SUMIFS('Additions (monthly)'!$E$2:$E$106,'Additions (monthly)'!$D$2:$D$106,I$2,'Additions (monthly)'!$B$2:$B$106,"<="&$B11) -> 0 | J11: =SUMIFS('Additions (monthly)'!$E$2:$E$106,'Additions (monthly)'!$D$2:$D$106,J$2,'Additions (monthly)'!$B$2:$B$106,"<="&$B11) -> 3.7 | K11: =SUMIFS('Additions (monthly)'!$E$2:$E$106,'Additions (monthly)'!$D$2:$D$106,K$2,'Additions (monthly)'!$B$2:$B$106,"<="&$B11) -> 0 | ... BI11: =SUMIFS('Additions (monthly)'!$E$2:$E$106,'Additions (monthly)'!$D$2:$D$106,BI$2,'Additions (monthly)'!$B$2:$B$106,"<="&$B11) -> 6.7
A12: 40452 | B12: 201010 | C12: =SUMIFS('Additions (monthly)'!$E$2:$E$106,'Additions (monthly)'!$B$2:$B$106,"<="&$B12) -> 247.67 | D12: =SUMIFS('Additions (monthly)'!$E$2:$E$106,'Additions (monthly)'!$D$2:$D$106,D$2,'Additions (monthly)'!$B$2:$B$106,"<="&$B12) -> 7.9 | E12: =SUMIFS('Additions (monthly)'!$E$2:$E$106,'Additions (monthly)'!$D$2:$D$106,E$2,'Additions (monthly)'!$B$2:$B$106,"<="&$B12) -> 8.4 | F12: =SUMIFS('Additions (monthly)'!$E$2:$E$106,'Additions (monthly)'!$D$2:$D$106,F$2,'Additions (monthly)'!$B$2:$B$106,"<="&$B12) -> 0 | G12: =SUMIFS('Additions (monthly)'!$E$2:$E$106,'Additions (monthly)'!$D$2:$D$106,G$2,'Additions (monthly)'!$B$2:$B$106,"<="&$B12) -> 0 | H12: =SUMIFS('Additions (monthly)'!$E$2:$E$106,'Additions (monthly)'!$D$2:$D$106,H$2,'Additions (monthly)'!$B$2:$B$106,"<="&$B12) -> 0 | I12: =SUMIFS('Additions (monthly)'!$E$2:$E$106,'Additions (monthly)'!$D$2:$D$106,I$2,'Additions (monthly)'!$B$2:$B$106,"<="&$B12) -> 0 | J12: =SUMIFS('Additions (monthly)'!$E$2:$E$106,'Additions (monthly)'!$D$2:$D$106,J$2,'Additions (monthly)'!$B$2:$B$106,"<="&$B12) -> 3.7 | K12: =SUMIFS('Additions (monthly)'!$E$2:$E$106,'Additions (monthly)'!$D$2:$D$106,K$2,'Additions (monthly)'!$B$2:$B$106,"<="&$B12) -> 0 | ... BI12: =SUMIFS('Additions (monthly)'!$E$2:$E$106,'Additions (monthly)'!$D$2:$D$106,BI$2,'Additions (monthly)'!$B$2:$B$106,"<="&$B12) -> 6.7
A13: 40483 | B13: 201011 | C13: =SUMIFS('Additions (monthly)'!$E$2:$E$106,'Additions (monthly)'!$B$2:$B$106,"<="&$B13) -> 255.77 | D13: =SUMIFS('Additions (monthly)'!$E$2:$E$106,'Additions (monthly)'!$D$2:$D$106,D$2,'Additions (monthly)'!$B$2:$B$106,"<="&$B13) -> 7.9 | E13: =SUMIFS('Additions (monthly)'!$E$2:$E$106,'Additions (monthly)'!$D$2:$D$106,E$2,'Additions (monthly)'!$B$2:$B$106,"<="&$B13) -> 8.4 | F13: =SUMIFS('Additions (monthly)'!$E$2:$E$106,'Additions (monthly)'!$D$2:$D$106,F$2,'Additions (monthly)'!$B$2:$B$106,"<="&$B13) -> 0 | G13: =SUMIFS('Additions (monthly)'!$E$2:$E$106,'Additions (monthly)'!$D$2:$D$106,G$2,'Additions (monthly)'!$B$2:$B$106,"<="&$B13) -> 0 | H13: =SUMIFS('Additions (monthly)'!$E$2:$E$106,'Additions (monthly)'!$D$2:$D$106,H$2,'Additions (monthly)'!$B$2:$B$106,"<="&$B13) -> 0 | I13: =SUMIFS('Additions (monthly)'!$E$2:$E$106,'Additions (monthly)'!$D$2:$D$106,I$2,'Additions (monthly)'!$B$2:$B$106,"<="&$B13) -> 0 | J13: =SUMIFS('Additions (monthly)'!$E$2:$E$106,'Additions (monthly)'!$D$2:$D$106,J$2,'Additions (monthly)'!$B$2:$B$106,"<="&$B13) -> 3.7 | K13: =SUMIFS('Additions (monthly)'!$E$2:$E$106,'Additions (monthly)'!$D$2:$D$106,K$2,'Additions (monthly)'!$B$2:$B$106,"<="&$B13) -> 0 | ... BI13: =SUMIFS('Additions (monthly)'!$E$2:$E$106,'Additions (monthly)'!$D$2:$D$106,BI$2,'Additions (monthly)'!$B$2:$B$106,"<="&$B13) -> 6.7
A14: 40513 | B14: 201012 | C14: =SUMIFS('Additions (monthly)'!$E$2:$E$106,'Additions (monthly)'!$B$2:$B$106,"<="&$B14) -> 255.77 | D14: =SUMIFS('Additions (monthly)'!$E$2:$E$106,'Additions (monthly)'!$D$2:$D$106,D$2,'Additions (monthly)'!$B$2:$B$106,"<="&$B14) -> 7.9 | E14: =SUMIFS('Additions (monthly)'!$E$2:$E$106,'Additions (monthly)'!$D$2:$D$106,E$2,'Additions (monthly)'!$B$2:$B$106,"<="&$B14) -> 8.4 | F14: =SUMIFS('Additions (monthly)'!$E$2:$E$106,'Additions (monthly)'!$D$2:$D$106,F$2,'Additions (monthly)'!$B$2:$B$106,"<="&$B14) -> 0 | G14: =SUMIFS('Additions (monthly)'!$E$2:$E$106,'Additions (monthly)'!$D$2:$D$106,G$2,'Additions (monthly)'!$B$2:$B$106,"<="&$B14) -> 0 | H14: =SUMIFS('Additions (monthly)'!$E$2:$E$106,'Additions (monthly)'!$D$2:$D$106,H$2,'Additions (monthly)'!$B$2:$B$106,"<="&$B14) -> 0 | I14: =SUMIFS('Additions (monthly)'!$E$2:$E$106,'Additions (monthly)'!$D$2:$D$106,I$2,'Additions (monthly)'!$B$2:$B$106,"<="&$B14) -> 0 | J14: =SUMIFS('Additions (monthly)'!$E$2:$E$106,'Additions (monthly)'!$D$2:$D$106,J$2,'Additions (monthly)'!$B$2:$B$106,"<="&$B14) -> 3.7 | K14: =SUMIFS('Additions (monthly)'!$E$2:$E$106,'Additions (monthly)'!$D$2:$D$106,K$2,'Additions (monthly)'!$B$2:$B$106,"<="&$B14) -> 0 | ... BI14: =SUMIFS('Additions (monthly)'!$E$2:$E$106,'Additions (monthly)'!$D$2:$D$106,BI$2,'Additions (monthly)'!$B$2:$B$106,"<="&$B14) -> 6.7
... A206: 46357 | B206: 202612 | C206: =SUMIFS('Additions (monthly)'!$E$2:$E$106,'Additions (monthly)'!$B$2:$B$106,"<="&$B206) -> 565.07 | D206: =SUMIFS('Additions (monthly)'!$E$2:$E$106,'Additions (monthly)'!$D$2:$D$106,D$2,'Additions (monthly)'!$B$2:$B$106,"<="&$B206) -> 7.9 | E206: =SUMIFS('Additions (monthly)'!$E$2:$E$106,'Additions (monthly)'!$D$2:$D$106,E$2,'Additions (monthly)'!$B$2:$B$106,"<="&$B206) -> 8.4 | F206: =SUMIFS('Additions (monthly)'!$E$2:$E$106,'Additions (monthly)'!$D$2:$D$106,F$2,'Additions (monthly)'!$B$2:$B$106,"<="&$B206) -> 4.7 | G206: =SUMIFS('Additions (monthly)'!$E$2:$E$106,'Additions (monthly)'!$D$2:$D$106,G$2,'Additions (monthly)'!$B$2:$B$106,"<="&$B206) -> 4.5 | H206: =SUMIFS('Additions (monthly)'!$E$2:$E$106,'Additions (monthly)'!$D$2:$D$106,H$2,'Additions (monthly)'!$B$2:$B$106,"<="&$B206) -> 5.2 | I206: =SUMIFS('Additions (monthly)'!$E$2:$E$106,'Additions (monthly)'!$D$2:$D$106,I$2,'Additions (monthly)'!$B$2:$B$106,"<="&$B206) -> 9 | J206: =SUMIFS('Additions (monthly)'!$E$2:$E$106,'Additions (monthly)'!$D$2:$D$106,J$2,'Additions (monthly)'!$B$2:$B$106,"<="&$B206) -> 3.7 | K206: =SUMIFS('Additions (monthly)'!$E$2:$E$106,'Additions (monthly)'!$D$2:$D$106,K$2,'Additions (monthly)'!$B$2:$B$106,"<="&$B206) -> 7.8 | ... BI206: =SUMIFS('Additions (monthly)'!$E$2:$E$106,'Additions (monthly)'!$D$2:$D$106,BI$2,'Additions (monthly)'!$B$2:$B$106,"<="&$B206) -> 6.7
A208: MONTH-BY-MONTH LNG EXPORT (LIQUEFACTION) NAMEPLATE CAPACITY, Mtpa, Jan 2010 – Dec 2026. Each cell = terminal nameplate operational as of month-end (cumulative). Global Total & terminal columns are live SUMIFS over "Additions (monthly)".
A209: 2026 ADDITIONS (from IEA Global LNG Capacity Tracker + operator news): Golden Pass T1 (Mar) & T2 (Oct), LNG Canada T2, Corpus Christi Stage 3 T5-T7, ECA Mexico (Jun), Congo Nguya FLNG (Feb), Qatar NFE T1 (~Sep), Pluto T2/Scarborough (~Nov). Global total: 524.55 (Dec 2025) → 565.07 Mtpa (Dec 2026).
A210: IEA GAPS: some H1-2026 startups the IEA tracker had not yet logged are included from news (e.g., Congo Nguya FLNG, Golden Pass T1, ECA). H2-2026 items (NFE, Golden Pass T2, Pluto T2, Corpus T7) are expected/forecast and carry slippage risk. Plaquemines is already at full nameplate (19.44) from 2025 — its 2026 "ramp" is output, not nameplate, so not re-added.
A211: Nameplate only — not actual output. See "Monthly outages (Mtpa)" for estimated capacity offline; net available = capacity − outages.

Sheet Commissioning schedule
A1: Commissioning Month | B1: Month (date) | C1: Country | D1: Terminal | E1: Trains added | F1: Capacity added (Mtpa) | G1: Cumulative capacity (Mtpa) | H1: IGU start year | I1: Basis | J1: Conf. | K1: Notes | L1: Source
A2: ≤2009 (baseline) | B2: 40148 | C2: — | D2: Pre-2010 baseline — all plants online before 2010 (55 trains) | E2: 55 | F2: 239.4 | G2: 239.4 | H2: ≤2009 | I2: operating | J2: — | K2: Sum of all trains with start year ≤2009; already online at Jan 2010 | L2: IGU WLR 2026 App.1
A3: 2010-01 | B3: 40179 | C3: China | D3: Inland facilities | E3: 1 | F3: 3.87 | G3: =G2+F3 -> 243.27 | H3: 2010 | I3: baseline | J3: High | K3: Aggregate pre-2010 small-scale inland capacity; treated as online at Jan 2010
A4: 2010-06 | B4: 40330 | C4: Peru | D4: Peru LNG | E4: 1 | F4: 4.45 | G4: =G3+F4 -> 247.72 | H4: 2010 | I4: first-cargo | J4: High | K4: First cargo 22 Jun 2010 | L4: https://www.prnewswire.com/news-releases/peru-lng-inaugurates-the-first-natural-gas-liquefaction-lng-plant-in-south-america-96065044.html
A5: 2010-11 | B5: 40483 | C5: Norway | D5: Nordic LNG | E5: 1 | F5: 0.3 | G5: =G4+F5 -> 248.02 | H5: 2010 | I5: first-LNG | J5: Low | K5: Official opening Oct 2011; commissioning ~late 2010 | L5: https://www.gem.wiki/Risavika_LNG_Terminal
A6: 2010-11 | B6: 40483 | C6: Qatar | D6: QatarGas LNG | E6: 1 | F6: 7.8 | G6: =G5+F6 -> 255.82 | H6: 2010 | I6: first-LNG | J6: High | K6: First LNG 1 Nov 2010 | L6: https://www.offshore-energy.biz/qatargas-train-6-produces-first-lng/
A7: 2011-02 | B7: 40575 | C7: Qatar | D7: QatarGas LNG | E7: 1 | F7: 7.8 | G7: =G6+F7 -> 263.62 | H7: 2011 | I7: first-LNG | J7: Med | K7: Operations announced 10 Feb 2011 | L7: https://www.ogj.com/pipelines-transportation/lng/article/17267015/qatargas-4s-train-7-begins-operations
A8: 2012-04 | B8: 41000 | C8: Australia | D8: Pluto LNG | E8: 1 | F8: 4.9 | G8: =G7+F8 -> 268.52 | H8: 2012 | I8: first-LNG | J8: High | K8: Woodside start 30 Apr 2012; first cargo May 2012 | L8: https://www.bloomberg.com/news/articles/2012-04-30/woodside-starts-lng-production-at-pluto-development-in-australia
A9: 2013-03 | B9: 41334 | C9: Algeria | D9: Skikda GL1K | E9: 1 | F9: 4.5 | G9: =G8+F9 -> 273.02 | H9: 2013 | I9: first-LNG | J9: Low | K9: Rebuilt train after 2004 explosion; ~2013 | L9: https://www.gem.wiki/Sonatrach_Skikda_LNG_Terminal
A10: 2013-06 | B10: 41426 | C10: Angola | D10: Angola LNG | E10: 1 | F10: 5.2 | G10: =G9+F10 -> 278.22 | H10: 2013 | I10: first-cargo | J10: High | K10: First cargo 16 Jun 2013 | L10: https://www.prnewswire.com/news-releases/angola-lng-ships-first-cargo-211725271.html
A11: 2014-04 | B11: 41730 | C11: Papua New Guinea | D11: PNG LNG | E11: 2 | F11: 6.9 | G11: =G10+F11 -> 285.12 | H11: 2014 | I11: first-LNG | J11: High | K11: Start-up 28 Apr 2014; first cargo May 2014 | L11: https://investor.exxonmobil.com/company-information/press-releases/detail/564/exxonmobil-starts-production-ahead-of-schedule-at-png-lng
A12: 2014-11 | B12: 41944 | C12: Algeria | D12: Arzew GL3Z (Gassi Touil) | E12: 1 | F12: 4.7 | G12: =G11+F12 -> 289.82 | H12: 2014 | I12: first-LNG | J12: Med | K12: Project completed Nov 2014 | L12: https://www.gem.wiki/Arzew-Bethioua_LNG_Terminal
A13: 2014-12 | B13: 41974 | C13: Australia | D13: Queensland Curtis LNG | E13: 2 | F13: 8.5 | G13: =G12+F13 -> 298.32 | H13: 2015 | I13: first-LNG | J13: High | K13: First LNG Dec 2014 (IGU lists 2015) | L13: https://www.oedigital.com/news/452553-qclng-begins-operations
A14: 2015-06 | B14: 42156 | C14: Indonesia | D14: Donggi- Senoro LNG | E14: 1 | F14: 2 | G14: =G13+F14 -> 300.32 | H14: 2015 | I14: first-LNG | J14: Med | K14: Commissioning ~Jun; first cargo Aug 2015 | L14: https://www.gem.wiki/Donggi-Senoro_LNG_Terminal
A15: 2015-09 | B15: 42248 | C15: Australia | D15: GLNG | E15: 1 | F15: 3.9 | G15: =G14+F15 -> 304.22 | H15: 2015 | I15: first-LNG | J15: High | K15: First LNG 24 Sep 2015 | L15: https://www.santos.com/news/2015-glng-starts-lng-production-on-schedule/
... A54: 2025-06 | B54: 45809 | C54: United States | D54: Plaquemines LNG | E54: 28 | F54: 15.12 | G54: =G53+F54 -> 524.6 | H54: 2025 | I54: commercial-start | J54: Low | K54: Representative month; multiple modular blocks online through 2025 | L54: https://www.eia.gov/todayinenergy/detail.php?id=64224
A56: HOW TO USE: rows are sorted by commissioning month. "Capacity added" is the nameplate step; "Cumulative capacity" forward-fills to give the export-capacity level. For a full month-by-month series, carry each cumulative value forward across the months until the next row.
A57: ORANGE ROWS: the researched first-LNG month falls in an EARLIER year than IGU's assigned "start year" (IGU tends to date plants to substantial-completion / commercial operations, not first commissioning LNG). Use the "IGU start year" column instead if you prefer to align with the annual file. This choice only shifts capacity by 1–2 months around a year boundary.
A58: BASIS: "first-LNG" = first commissioning production (preferred); "first-cargo" = first export shipment (first-LNG slightly earlier); "commercial-start" = declared commercial operations (first-LNG earlier). Confidence flags source certainty on the exact month.
A59: MODULAR PROJECTS (Calcasieu Pass, Plaquemines, Elba Island) ramp capacity over many months, not in a single step. The month shown is first-LNG; the full nameplate is reached gradually. For a precise monthly series these should be spread across their ramp — happy to model that.
A60: Cumulative reaches 524.55 Mtpa (end-2025), matching IGU WLR 2026 and GIIGNL (~524 Mtpa). Source: IGU World LNG Report 2026, Appendix 1, plus per-event commissioning sources listed per row.

Sheet Train detail
A1: RefNo | B1: Country | C1: Terminal | D1: Train | E1: Technology | F1: Start Year | G1: Capacity (Mtpa) | H1: Ownership | I1: Note
A2: 1 | B2: Brunei | C2: Brunei LNG | D2: Brunei LNG T1-T2 | E2: AP-C3MR | F2: 1972 | G2: 2.88 | H2: Shell* (25%); Brunei Government (50%); Mitsubishi Corp (25%)
A3: 1 | B3: Brunei | C3: Brunei LNG | D3: Brunei LNG T3-T4 | E3: AP-C3MR | F3: 1973 | G3: 2.88 | H3: Shell* (25%); Brunei Government (50%); Mitsubishi Corp (25%)
A4: 1 | B4: Brunei | C4: Brunei LNG | D4: Brunei LNG T5 | E4: AP-C3MR | F4: 1974 | G4: 1.44 | H4: Shell* (25%); Brunei Government (50%); Mitsubishi Corp (25%)
A5: 2 | B5: UAE | C5: Adgas LNG | D5: Adgas LNG T1 | E5: AP-C3MR | F5: 1977 | G5: 1.15 | H5: ADNOC LNG* (0%); ADNOC (70%); Mitsui (15%); BP (10%); TotalEnergies (5%)
A6: 2 | B6: UAE | C6: Adgas LNG | D6: Adgas LNG T2 | E6: AP-C3MR | F6: 1977 | G6: 1.15 | H6: ADNOC LNG* (0%); ADNOC (70%); Mitsui (15%); BP (10%); TotalEnergies (5%)
A7: 2 | B7: UAE | C7: Adgas LNG | D7: Adgas LNG T3 | E7: AP-C3MR | F7: 1994 | G7: 3 | H7: ADNOC LNG* (0%); ADNOC (70%); Mitsui (15%); BP (10%); TotalEnergies (5%)
A8: 3 | B8: Algeria | C8: Arzew GL1Z | D8: Arzew GL1Z T1-T6 | E8: AP-C3MR | F8: 1978 | G8: 7.9 | H8: Sonatrach* (100%)
A9: 4 | B9: Algeria | C9: Arzew GL2Z | D9: Arzew GL2Z T1-T6 | E9: AP-C3MR | F9: 1981 | G9: 8.4 | H9: Sonatrach* (100%)
A10: 5 | B10: Malaysia | C10: MLNG | D10: MLNG Satu T1-T3 | E10: AP-C3MR | F10: 1982 | G10: 8.4 | H10: Petronas* (90%); Mitsubishi Corp (5%); Sarawak State (5%)
A11: 5 | B11: Malaysia | C11: MLNG | D11: MLNG Dua T4-T6 | E11: AP-C3MR | F11: 1995 | G11: 9.6 | H11: Petronas* (80%); Mitsubishi Corp (10%); Sarawak State (10%)
A12: 5 | B12: Malaysia | C12: MLNG | D12: MLNG Tiga T7-T8 | E12: AP-C3MR | F12: 2003 | G12: 7.7 | H12: Petronas* (60%); Sarawak State (25%); JX Nippon Oil and Gas (10%); Mitsubishi Corp (5%)
A13: 5 | B13: Malaysia | C13: MLNG | D13: MLNG T9 | E13: AP-C3MR/ SplitMR | F13: 2017 | G13: 3.6 | H13: Petronas* (80%); JX Nippon Oil and Gas (10%); Sarawak State (10%)
... A180: 53 | B180: Canada | C180: LNG Canada | D180: LNG Canada T1 | E180: Shell DMR | F180: 2025 | G180: 7 | H180: Shell* (40%); Petronas (20%); MidOcean Energy (5%); Mitsubishi Corp (15%); PetroChina (15%); Korea Gas (5%);
A181: 54 | B181: China | C181: Inland facilities | D181: - | E181: - | F181: 2010 | G181: 3.87 | H181: - | I181: Start year not given in source; set to 2010 for inclusion

Sheet Terminal x Year
A1: Country | B1: Terminal | C1: First Online | D1: Nameplate end-2025 (Mtpa) | E1: 2010 | F1: 2011 | G1: 2012 | H1: 2013 | I1: 2014 | J1: 2015 | K1: 2016 | L1: 2017 | M1: 2018 | N1: 2019 | O1: 2020 | P1: 2021 | Q1: 2022 | R1: 2023 | S1: 2024 | T1: 2025
A2: Brunei | B2: Brunei LNG | C2: 1972 | D2: =SUMIFS('Train detail'!$G$2:$G$181,'Train detail'!$B$2:$B$181,$A2,'Train detail'!$C$2:$C$181,$B2) -> 7.2 | E2: =SUMIFS('Train detail'!$G$2:$G$181,'Train detail'!$B$2:$B$181,$A2,'Train detail'!$C$2:$C$181,$B2,'Train detail'!$F$2:$F$181,"<="&2010) -> 7.2 | F2: =SUMIFS('Train detail'!$G$2:$G$181,'Train detail'!$B$2:$B$181,$A2,'Train detail'!$C$2:$C$181,$B2,'Train detail'!$F$2:$F$181,"<="&2011) -> 7.2 | G2: =SUMIFS('Train detail'!$G$2:$G$181,'Train detail'!$B$2:$B$181,$A2,'Train detail'!$C$2:$C$181,$B2,'Train detail'!$F$2:$F$181,"<="&2012) -> 7.2 | H2: =SUMIFS('Train detail'!$G$2:$G$181,'Train detail'!$B$2:$B$181,$A2,'Train detail'!$C$2:$C$181,$B2,'Train detail'!$F$2:$F$181,"<="&2013) -> 7.2 | I2: =SUMIFS('Train detail'!$G$2:$G$181,'Train detail'!$B$2:$B$181,$A2,'Train detail'!$C$2:$C$181,$B2,'Train detail'!$F$2:$F$181,"<="&2014) -> 7.2 | J2: =SUMIFS('Train detail'!$G$2:$G$181,'Train detail'!$B$2:$B$181,$A2,'Train detail'!$C$2:$C$181,$B2,'Train detail'!$F$2:$F$181,"<="&2015) -> 7.2 | K2: =SUMIFS('Train detail'!$G$2:$G$181,'Train detail'!$B$2:$B$181,$A2,'Train detail'!$C$2:$C$181,$B2,'Train detail'!$F$2:$F$181,"<="&2016) -> 7.2 | L2: =SUMIFS('Train detail'!$G$2:$G$181,'Train detail'!$B$2:$B$181,$A2,'Train detail'!$C$2:$C$181,$B2,'Train detail'!$F$2:$F$181,"<="&2017) -> 7.2 | M2: =SUMIFS('Train detail'!$G$2:$G$181,'Train detail'!$B$2:$B$181,$A2,'Train detail'!$C$2:$C$181,$B2,'Train detail'!$F$2:$F$181,"<="&2018) -> 7.2 | N2: =SUMIFS('Train detail'!$G$2:$G$181,'Train detail'!$B$2:$B$181,$A2,'Train detail'!$C$2:$C$181,$B2,'Train detail'!$F$2:$F$181,"<="&2019) -> 7.2 | O2: =SUMIFS('Train detail'!$G$2:$G$181,'Train detail'!$B$2:$B$181,$A2,'Train detail'!$C$2:$C$181,$B2,'Train detail'!$F$2:$F$181,"<="&2020) -> 7.2 | P2: =SUMIFS('Train detail'!$G$2:$G$181,'Train detail'!$B$2:$B$181,$A2,'Train detail'!$C$2:$C$181,$B2,'Train detail'!$F$2:$F$181,"<="&2021) -> 7.2 | Q2: =SUMIFS('Train detail'!$G$2:$G$181,'Train detail'!$B$2:$B$181,$A2,'Train detail'!$C$2:$C$181,$B2,'Train detail'!$F$2:$F$181,"<="&2022) -> 7.2 | R2: =SUMIFS('Train detail'!$G$2:$G$181,'Train detail'!$B$2:$B$181,$A2,'Train detail'!$C$2:$C$181,$B2,'Train detail'!$F$2:$F$181,"<="&2023) -> 7.2 | S2: =SUMIFS('Train detail'!$G$2:$G$181,'Train detail'!$B$2:$B$181,$A2,'Train detail'!$C$2:$C$181,$B2,'Train detail'!$F$2:$F$181,"<="&2024) -> 7.2 | T2: =SUMIFS('Train detail'!$G$2:$G$181,'Train detail'!$B$2:$B$181,$A2,'Train detail'!$C$2:$C$181,$B2,'Train detail'!$F$2:$F$181,"<="&2025) -> 7.2
