Workbook

Sheet Transform
A1: Date | B1: Production(bcm) | C1: Electricity(bcm) | D1: Total(bcm) | E1: Non_power(bcm) | F1: Stock_change(bcm) | G1: Distribution_loss(bcm) | H1: Total_adj(bcm)
A2: 2015-01 | B2: =EU!B2+UK!B2 -> 17.469 | C2: =EU!C2+UK!C2 -> 5.798 | D2: =EU!D2+UK!D2 -> 55.776 | E2: =EU!E2+UK!E2 -> 49.978 | F2: -15.741 | G2: 0.364 | H2: =EU!H2+UK!D2 -> 56.173479
A3: 2015-02 | B3: =EU!B3+UK!B3 -> 15.724 | C3: =EU!C3+UK!C3 -> 6.594 | D3: =EU!D3+UK!D3 -> 51.439 | E3: =EU!E3+UK!E3 -> 44.845 | F3: -15.736 | G3: 0.336 | H3: =EU!H3+UK!D3 -> 51.806486
A4: 2015-03 | B4: =EU!B4+UK!B4 -> 13.854 | C4: =EU!C4+UK!C4 -> 5.542 | D4: =EU!D4+UK!D4 -> 45.44 | E4: =EU!E4+UK!E4 -> 39.898 | F4: -7.882 | G4: 0.364 | H4: =EU!H4+UK!D4 -> 45.761031
A5: 2015-04 | B5: =EU!B5+UK!B5 -> 10.318 | C5: =EU!C5+UK!C5 -> 4.696 | D5: =EU!D5+UK!D5 -> 33.304 | E5: =EU!E5+UK!E5 -> 28.608 | F5: 0.455 | G5: 0.3 | H5: =EU!H5+UK!D5 -> 33.541126
A6: 2015-05 | B6: =EU!B6+UK!B6 -> 9.427 | C6: =EU!C6+UK!C6 -> 4.337 | D6: =EU!D6+UK!D6 -> 26.775 | E6: =EU!E6+UK!E6 -> 22.438 | F6: 7.264 | G6: 0.295 | H6: =EU!H6+UK!D6 -> 26.961502
A7: 2015-06 | B7: =EU!B7+UK!B7 -> 9.066 | C7: =EU!C7+UK!C7 -> 4.544 | D7: =EU!D7+UK!D7 -> 23.817 | E7: =EU!E7+UK!E7 -> 19.273 | F7: 8.363 | G7: 0.297 | H7: =EU!H7+UK!D7 -> 23.984529
A8: 2015-07 | B8: =EU!B8+UK!B8 -> 8.087 | C8: =EU!C8+UK!C8 -> 6.264 | D8: =EU!D8+UK!D8 -> 24.164 | E8: =EU!E8+UK!E8 -> 17.9 | F8: 10.409 | G8: 0.328 | H8: =EU!H8+UK!D8 -> 24.337466
A9: 2015-08 | B9: =EU!B9+UK!B9 -> 8.111 | C9: =EU!C9+UK!C9 -> 5.94 | D9: =EU!D9+UK!D9 -> 22.277 | E9: =EU!E9+UK!E9 -> 16.337 | F9: 9.756 | G9: 0.375 | H9: =EU!H9+UK!D9 -> 22.434449
A10: 2015-09 | B10: =EU!B10+UK!B10 -> 9.18 | C10: =EU!C10+UK!C10 -> 5.993 | D10: =EU!D10+UK!D10 -> 26.418 | E10: =EU!E10+UK!E10 -> 20.425 | F10: 8.748 | G10: 0.303 | H10: =EU!H10+UK!D10 -> 26.604271
A11: 2015-10 | B11: =EU!B11+UK!B11 -> 10.836 | C11: =EU!C11+UK!C11 -> 6.765 | D11: =EU!D11+UK!D11 -> 36.201 | E11: =EU!E11+UK!E11 -> 29.436 | F11: 1.964 | G11: 0.349 | H11: =EU!H11+UK!D11 -> 36.461618
A12: 2015-11 | B12: =EU!B12+UK!B12 -> 12.219 | C12: =EU!C12+UK!C12 -> 7.97 | D12: =EU!D12+UK!D12 -> 41.847 | E12: =EU!E12+UK!E12 -> 33.877 | F12: -4.14 | G12: 0.351 | H12: =EU!H12+UK!D12 -> 42.144957
A13: 2015-12 | B13: =EU!B13+UK!B13 -> 13.131 | C13: =EU!C13+UK!C13 -> 8.104 | D13: =EU!D13+UK!D13 -> 46.904 | E13: =EU!E13+UK!E13 -> 38.8 | F13: -7.28 | G13: 0.407 | H13: =EU!H13+UK!D13 -> 47.245115
... A49: 2018-12 | B49: =EU!B49+UK!B49 -> 10.587 | C49: =EU!C49+UK!C49 -> 10.1907 | D49: =EU!D49+UK!D49 -> 53.1017 | E49: =EU!E49+UK!E49 -> 42.911 | F49: -8.278 | G49: 0.3447 | H49: =EU!H49+UK!D49 -> 54.160711
A50: 2019-01 | B50: =EU!B50+UK!B50 -> 10.758 | C50: =EU!C50+UK!C50 -> 10.914252 | D50: =EU!D50+UK!D50 -> 65.767269 | E50: =EU!E50+UK!E50 -> 54.853017 | H50: =EU!H50+UK!D50 -> 66.280729
A51: 2019-02 | B51: =EU!B51+UK!B51 -> 9.403 | C51: =EU!C51+UK!C51 -> 8.8292349 | D51: =EU!D51+UK!D51 -> 51.39707 | E51: =EU!E51+UK!E51 -> 42.567835 | F51: -10.749205 | H51: =EU!H51+UK!D51 -> 51.799389
A52: 2019-03 | B52: =EU!B52+UK!B52 -> 10.080302 | C52: =EU!C52+UK!C52 -> 8.4894144 | D52: =EU!D52+UK!D52 -> 46.90978 | E52: =EU!E52+UK!E52 -> 38.420366 | F52: -0.959285 | G52: 0.371367 | H52: =EU!H52+UK!D52 -> 47.272275
A53: 2019-04 | B53: =EU!B53+UK!B53 -> 9.058 | C53: =EU!C53+UK!C53 -> 7.4613542 | D53: =EU!D53+UK!D53 -> 36.686605 | E53: =EU!E53+UK!E53 -> 29.225251 | F53: 7.919912 | H53: =EU!H53+UK!D53 -> 36.966749
A54: 2019-05 | B54: =EU!B54+UK!B54 -> 9.434 | C54: =EU!C54+UK!C54 -> 8.1777644 | D54: =EU!D54+UK!D54 -> 33.258011 | E54: =EU!E54+UK!E54 -> 25.080247 | F54: 11.754903 | H54: =EU!H54+UK!D54 -> 33.515403
A55: 2019-06 | B55: =EU!B55+UK!B55 -> 8.488 | C55: =EU!C55+UK!C55 -> 8.1101749 | D55: =EU!D55+UK!D55 -> 26.013858 | E55: =EU!E55+UK!E55 -> 17.903683 | F55: 14.133253 | H55: =EU!H55+UK!D55 -> 26.212119
A56: 2019-07 | B56: =EU!B56+UK!B56 -> 8.749 | C56: =EU!C56+UK!C56 -> 9.3442795 | D56: =EU!D56+UK!D56 -> 28.906602 | E56: =EU!E56+UK!E56 -> 19.562323 | F56: 10.236906 | H56: =EU!H56+UK!D56 -> 29.135264
A57: 2019-08 | B57: =EU!B57+UK!B57 -> 8.554 | C57: =EU!C57+UK!C57 -> 8.0479836 | D57: =EU!D57+UK!D57 -> 26.047242 | E57: =EU!E57+UK!E57 -> 17.999258 | F57: 9.918834 | H57: =EU!H57+UK!D57 -> 26.253691
A58: 2019-09 | B58: =EU!B58+UK!B58 -> 8.15 | C58: =EU!C58+UK!C58 -> 8.571976 | D58: =EU!D58+UK!D58 -> 29.333591 | E58: =EU!E58+UK!E58 -> 20.761615 | F58: 5.453081 | H58: =EU!H58+UK!D58 -> 29.56712
A59: 2019-10 | B59: =EU!B59+UK!B59 -> 8.916 | C59: =EU!C59+UK!C59 -> 9.5540017 | D59: =EU!D59+UK!D59 -> 38.699592 | E59: =EU!E59+UK!E59 -> 29.14559 | F59: 1.726854 | H59: =EU!H59+UK!D59 -> 38.994984
A60: 2019-11 | B60: =EU!B60+UK!B60 -> 9.063688 | C60: =EU!C60+UK!C60 -> 10.400069 | D60: =EU!D60+UK!D60 -> 49.499192 | E60: =EU!E60+UK!E60 -> 39.099123 | F60: -3.742252 | G60: 0.365975 | H60: =EU!H60+UK!D60 -> 49.877412
A61: 2019-12 | B61: =EU!B61+UK!B61 -> 9.354 | C61: =EU!C61+UK!C61 -> 9.8733426 | D61: =EU!D61+UK!D61 -> 54.214968 | E61: =EU!E61+UK!E61 -> 44.341625 | F61: -6.644534 | H61: =EU!H61+UK!D61 -> 54.635102
A62: 2020-01 | B62: =EU!B62+UK!B62 -> 9.388 | C62: =EU!C62+UK!C62 -> 11.842615 | D62: =EU!D62+UK!D62 -> 59.248794 | E62: =EU!E62+UK!E62 -> 47.406179 | H62: =EU!H62+UK!D62 -> 59.607447
A63: 2020-02 | B63: =EU!B63+UK!B63 -> 8.262 | C63: =EU!C63+UK!C63 -> 9.079694 | D63: =EU!D63+UK!D63 -> 49.820593 | E63: =EU!E63+UK!E63 -> 40.740899 | H63: =EU!H63+UK!D63 -> 50.115359
A64: 2020-03 | B64: =EU!B64+UK!B64 -> 8.23 | C64: =EU!C64+UK!C64 -> 8.7016 | D64: =EU!D64+UK!D64 -> 47.683111 | E64: =EU!E64+UK!E64 -> 38.981511 | H64: =EU!H64+UK!D64 -> 47.962807
A65: 2020-04 | B65: =EU!B65+UK!B65 -> 8.363 | C65: =EU!C65+UK!C65 -> 6.648042 | D65: =EU!D65+UK!D65 -> 30.466971 | E65: =EU!E65+UK!E65 -> 23.818929 | H65: =EU!H65+UK!D65 -> 30.645137
A66: 2020-05 | B66: =EU!B66+UK!B66 -> 8.6 | C66: =EU!C66+UK!C66 -> 6.766979 | D66: =EU!D66+UK!D66 -> 28.096816 | E66: =EU!E66+UK!E66 -> 21.329837 | H66: =EU!H66+UK!D66 -> 28.263692
A67: 2020-06 | B67: =EU!B67+UK!B67 -> 7.334 | C67: =EU!C67+UK!C67 -> 8.371773 | D67: =EU!D67+UK!D67 -> 26.365217 | E67: =EU!E67+UK!E67 -> 17.993444 | H67: =EU!H67+UK!D67 -> 26.522635
A68: 2020-07 | B68: =EU!B68+UK!B68 -> 7.285 | C68: =EU!C68+UK!C68 -> 10.200019 | D68: =EU!D68+UK!D68 -> 27.991234 | E68: =EU!E68+UK!E68 -> 17.791215 | H68: =EU!H68+UK!D68 -> 28.160365
A69: 2020-08 | B69: =EU!B69+UK!B69 -> 6.606 | C69: =EU!C69+UK!C69 -> 10.066887 | D69: =EU!D69+UK!D69 -> 26.603947 | E69: =EU!E69+UK!E69 -> 16.53706 | H69: =EU!H69+UK!D69 -> 26.764258
A70: 2020-09 | B70: =EU!B70+UK!B70 -> 6.147 | C70: =EU!C70+UK!C70 -> 9.540407 | D70: =EU!D70+UK!D70 -> 29.316635 | E70: =EU!E70+UK!E70 -> 19.776228 | H70: =EU!H70+UK!D70 -> 29.4928
A71: 2020-10 | B71: =EU!B71+UK!B71 -> 7.814 | C71: =EU!C71+UK!C71 -> 8.753523 | D71: =EU!D71+UK!D71 -> 38.801946 | E71: =EU!E71+UK!E71 -> 30.048423 | H71: =EU!H71+UK!D71 -> 39.030075
A72: 2020-11 | B72: =EU!B72+UK!B72 -> 7.69 | C72: =EU!C72+UK!C72 -> 10.258523 | D72: =EU!D72+UK!D72 -> 47.46376 | E72: =EU!E72+UK!E72 -> 37.205237 | H72: =EU!H72+UK!D72 -> 47.748233
A73: 2020-12 | B73: =EU!B73+UK!B73 -> 8.202 | C73: =EU!C73+UK!C73 -> 11.531474 | D73: =EU!D73+UK!D73 -> 57.417784 | E73: =EU!E73+UK!E73 -> 45.88631 | H73: =EU!H73+UK!D73 -> 57.759338
... A75: 2021-02 | B75: =EU!B75+UK!B75 -> 6.979734 | C75: =EU!C75+UK!C75 -> 9.511205 | D75: =EU!D75+UK!D75 -> 53.06425 | E75: =EU!E75+UK!E75 -> 43.553045 | H75: =EU!H75+UK!D75 -> 53.662522
A76: 2021-03 | B76: =EU!B76+UK!B76 -> 7.991315 | C76: =EU!C76+UK!C76 -> 10.337118 | D76: =EU!D76+UK!D76 -> 51.20375 | E76: =EU!E76+UK!E76 -> 40.866632 | F76: -7.199487 | G76: 0.389082 | H76: =EU!H76+UK!D76 -> 51.780332
...

Sheet EU
A1: Date | B1: Production(bcm) | C1: Electricity(bcm) | D1: Total(bcm) | E1: Non_power(bcm) | F1: Stock_change(bcm) | G1: Distribution_loss(bcm) | H1: Total_adj(bcm) | I1: Year | K1: Eurostat: | M1: Annual | N1: Monthly | O1: Diff | P1: Upward bias
A2: 2015-01 | B2: 13.833 | C2: 4.124 | D2: 46.529 | E2: =D2-C2 -> 42.405 | F2: -15.741 | G2: 0.364 | H2: =(_xlfn.XLOOKUP(I2,L:L,P:P)+100%)*D2 -> 46.926479 | I2: 2015 | L2: 2015 | M2: 365.28203 | N2: =SUM(D2:D13) -> 362.188 | O2: =M2-N2 -> 3.094028 | P2: =O2/N2 -> 0.0085426022
A3: 2015-02 | B3: 12.579 | C3: 4.46 | D3: 43.018 | E3: =D3-C3 -> 38.558 | F3: -15.736 | G3: 0.336 | H3: =(_xlfn.XLOOKUP(I3,L:L,P:P)+100%)*D3 -> 43.385486 | I3: 2015 | L3: 2016 | M3: 385.55353 | N3: =SUM(D14:D25) -> 382.464 | O3: =M3-N3 -> 3.089527 | P3: =O3/N3 -> 0.008077955
A4: 2015-03 | B4: 10.171 | C4: 4.036 | D4: 37.58 | E4: =D4-C4 -> 33.544 | F4: -7.882 | G4: 0.364 | H4: =(_xlfn.XLOOKUP(I4,L:L,P:P)+100%)*D4 -> 37.901031 | I4: 2015 | L4: 2017 | M4: 407.26572 | N4: =SUM(D26:D37) -> 404.6549 | O4: =M4-N4 -> 2.610815 | P4: =O4/N4 -> 0.0064519545
A5: 2015-04 | B5: 6.919 | C5: 3.349 | D5: 27.758 | E5: =D5-C5 -> 24.409 | F5: 0.455 | G5: 0.3 | H5: =(_xlfn.XLOOKUP(I5,L:L,P:P)+100%)*D5 -> 27.995126 | I5: 2015 | L5: 2018 | M5: 399.96701 | N5: =SUM(D38:D49) -> 390.5812 | O5: =M5-N5 -> 9.385812 | P5: =O5/N5 -> 0.024030373
A6: 2015-05 | B6: 5.511 | C6: 2.925 | D6: 21.832 | E6: =D6-C6 -> 18.907 | F6: 7.264 | G6: 0.295 | H6: =(_xlfn.XLOOKUP(I6,L:L,P:P)+100%)*D6 -> 22.018502 | I6: 2015 | L6: 2019 | M6: 411.18924 | N6: =SUM(D50:D61) -> 407.41278 | O6: =M6-N6 -> 3.776457 | P6: =O6/N6 -> 0.0092693631
A7: 2015-06 | B7: 5.713 | C7: 3.016 | D7: 19.611 | E7: =D7-C7 -> 16.595 | F7: 8.363 | G7: 0.297 | H7: =(_xlfn.XLOOKUP(I7,L:L,P:P)+100%)*D7 -> 19.778529 | I7: 2015 | L7: 2020 | M7: 398.73615 | N7: =SUM(D62:D73) -> 395.94081 | O7: =M7-N7 -> 2.795337 | P7: =O7/N7 -> 0.0070599871
A8: 2015-07 | B8: 4.984 | C8: 4.739 | D8: 20.306 | E8: =D8-C8 -> 15.567 | F8: 10.409 | G8: 0.328 | H8: =(_xlfn.XLOOKUP(I8,L:L,P:P)+100%)*D8 -> 20.479466 | I8: 2015 | L8: 2021 | M8: 417.95956 | N8: =SUM(D74:D85) -> 412.44576 | O8: =M8-N8 -> 5.513799 | P8: =O8/N8 -> 0.013368543
A9: 2015-08 | B9: 5.048 | C9: 4.358 | D9: 18.431 | E9: =D9-C9 -> 14.073 | F9: 9.756 | G9: 0.375 | H9: =(_xlfn.XLOOKUP(I9,L:L,P:P)+100%)*D9 -> 18.588449 | I9: 2015 | L9: 2022 | M9: 364.84148 | N9: =SUM(D86:D97) -> 355.68579 | O9: =M9-N9 -> 9.155695 | P9: =O9/N9 -> 0.025740964
A10: 2015-09 | B10: 6.229 | C10: 4.075 | D10: 21.805 | E10: =D10-C10 -> 17.73 | F10: 8.748 | G10: 0.303 | H10: =(_xlfn.XLOOKUP(I10,L:L,P:P)+100%)*D10 -> 21.991271 | I10: 2015 | L10: 2023 | M10: 334.42595 | N10: =SUM(D98:D109) -> 330.20052 | O10: =M10-N10 -> 4.225432 | P10: =O10/N10 -> 0.012796564
A11: 2015-10 | B11: 7.307 | C11: 4.833 | D11: 30.508 | E11: =D11-C11 -> 25.675 | F11: 1.964 | G11: 0.349 | H11: =(_xlfn.XLOOKUP(I11,L:L,P:P)+100%)*D11 -> 30.768618 | I11: 2015 | L11: 2024 | M11: 335.5964 | N11: =SUM(D110:D121) -> 331.6542 | O11: =M11-N11 -> 3.942204 | P11: =O11/N11 -> 0.011886489
A12: 2015-11 | B12: 8.514 | C12: 6.091 | D12: 34.879 | E12: =D12-C12 -> 28.788 | F12: -4.14 | G12: 0.351 | H12: =(_xlfn.XLOOKUP(I12,L:L,P:P)+100%)*D12 -> 35.176957 | I12: 2015 | L12: 2025 | P12: 0.01
A13: 2015-12 | B13: 9.303 | C13: 6.402 | D13: 39.931 | E13: =D13-C13 -> 33.529 | F13: -7.28 | G13: 0.407 | H13: =(_xlfn.XLOOKUP(I13,L:L,P:P)+100%)*D13 -> 40.272115 | I13: 2015 | L13: 2026 | P13: 0.01
A14: 2016-01 | B14: 9.391 | C14: 7.118 | D14: 49.373 | E14: =D14-C14 -> 42.255 | F14: -17.37 | G14: 0.402 | H14: =(_xlfn.XLOOKUP(I14,L:L,P:P)+100%)*D14 -> 49.771833 | I14: =I2+1 -> 2016
A15: 2016-02 | B15: 8.498 | C15: 5.572 | D15: 40.623 | E15: =D15-C15 -> 35.051 | F15: -10.918 | G15: 0.346 | H15: =(_xlfn.XLOOKUP(I15,L:L,P:P)+100%)*D15 -> 40.951151 | I15: =I3+1 -> 2016
A16: 2016-03 | B16: 6.19 | C16: 5.076 | D16: 37.129 | E16: =D16-C16 -> 32.053 | F16: -9.14 | G16: 0.337 | H16: =(_xlfn.XLOOKUP(I16,L:L,P:P)+100%)*D16 -> 37.428926 | I16: =I4+1 -> 2016
A17: 2016-04 | B17: 7.362 | C17: 4.351 | D17: 27.435 | E17: =D17-C17 -> 23.084 | F17: 4.476 | G17: 0.32 | H17: =(_xlfn.XLOOKUP(I17,L:L,P:P)+100%)*D17 -> 27.656619 | I17: =I5+1 -> 2016
A18: 2016-05 | B18: 7.444 | C18: 3.373 | D18: 22.559 | E18: =D18-C18 -> 19.186 | F18: 9.893 | G18: 0.315 | H18: =(_xlfn.XLOOKUP(I18,L:L,P:P)+100%)*D18 -> 22.741231 | I18: =I6+1 -> 2016
A19: 2016-06 | B19: 6.087 | C19: 4.078 | D19: 19.53 | E19: =D19-C19 -> 15.452 | F19: 11.628 | G19: 0.277 | H19: =(_xlfn.XLOOKUP(I19,L:L,P:P)+100%)*D19 -> 19.687762 | I19: =I7+1 -> 2016
A20: 2016-07 | B20: 6.357 | C20: 4.879 | D20: 20.374 | E20: =D20-C20 -> 15.495 | F20: 12.667 | G20: 0.341 | H20: =(_xlfn.XLOOKUP(I20,L:L,P:P)+100%)*D20 -> 20.53858 | I20: =I8+1 -> 2016
A21: 2016-08 | B21: 6.651 | C21: 4.136 | D21: 19.733 | E21: =D21-C21 -> 15.597 | F21: 9.566 | G21: 0.305 | H21: =(_xlfn.XLOOKUP(I21,L:L,P:P)+100%)*D21 -> 19.892402 | I21: =I9+1 -> 2016
A22: 2016-09 | B22: 6.608 | C22: 5.234 | D22: 22.365 | E22: =D22-C22 -> 17.131 | F22: 5.997 | G22: 0.304 | H22: =(_xlfn.XLOOKUP(I22,L:L,P:P)+100%)*D22 -> 22.545663 | I22: =I10+1 -> 2016
A23: 2016-10 | B23: 7.681 | C23: 6.005 | D23: 32.328 | E23: =D23-C23 -> 26.323 | F23: 0.515 | G23: 0.389 | H23: =(_xlfn.XLOOKUP(I23,L:L,P:P)+100%)*D23 -> 32.589144 | I23: =I11+1 -> 2016
A24: 2016-11 | B24: 8.528 | C24: 5.768 | D24: 42.086 | E24: =D24-C24 -> 36.318 | F24: -10.864 | G24: 0.397 | H24: =(_xlfn.XLOOKUP(I24,L:L,P:P)+100%)*D24 -> 42.425969 | I24: =I12+1 -> 2016
A25: 2016-12 | B25: 9.103 | C25: 7.104 | D25: 48.929 | E25: =D25-C25 -> 41.825 | F25: -16.68 | G25: 0.417 | H25: =(_xlfn.XLOOKUP(I25,L:L,P:P)+100%)*D25 -> 49.324246 | I25: =I13+1 -> 2016
... A49: 2018-12 | B49: 6.994 | C49: 7.6917 | D49: 44.0697 | E49: =D49-C49 -> 36.378 | F49: -8.278 | G49: 0.3447 | H49: =(_xlfn.XLOOKUP(I49,L:L,P:P)+100%)*D49 -> 45.128711 | I49: =I37+1 -> 2018
A50: 2019-01 | B50: 6.96 | C50: 8.6442516 | D50: 55.393269 | E50: =D50-C50 -> 46.749017 | H50: =(_xlfn.XLOOKUP(I50,L:L,P:P)+100%)*D50 -> 55.906729 | I50: =I38+1 -> 2019
A51: 2019-02 | B51: 6.075 | C51: 6.7902349 | D51: 43.40307 | E51: =D51-C51 -> 36.612835 | F51: -10.749205 | H51: =(_xlfn.XLOOKUP(I51,L:L,P:P)+100%)*D51 -> 43.805389 | I51: =I39+1 -> 2019
A52: 2019-03 | B52: 6.524302 | C52: 6.3704144 | D52: 39.10678 | E52: =D52-C52 -> 32.736366 | F52: -0.959285 | G52: 0.371367 | H52: =(_xlfn.XLOOKUP(I52,L:L,P:P)+100%)*D52 -> 39.469275 | I52: =I40+1 -> 2019
A53: 2019-04 | B53: 5.746 | C53: 5.6133542 | D53: 30.222605 | E53: =D53-C53 -> 24.609251 | F53: 7.919912 | H53: =(_xlfn.XLOOKUP(I53,L:L,P:P)+100%)*D53 -> 30.502749 | I53: =I41+1 -> 2019
A54: 2019-05 | B54: 6.041 | C54: 5.9097644 | D54: 27.768011 | E54: =D54-C54 -> 21.858247 | F54: 11.754903 | H54: =(_xlfn.XLOOKUP(I54,L:L,P:P)+100%)*D54 -> 28.025403 | I54: =I42+1 -> 2019
A55: 2019-06 | B55: 5.622 | C55: 5.7801749 | D55: 21.388858 | E55: =D55-C55 -> 15.608683 | F55: 14.133253 | H55: =(_xlfn.XLOOKUP(I55,L:L,P:P)+100%)*D55 -> 21.587119 | I55: =I43+1 -> 2019
A56: 2019-07 | B56: 5.625 | C56: 6.9372795 | D56: 24.668602 | E56: =D56-C56 -> 17.731323 | F56: 10.236906 | H56: =(_xlfn.XLOOKUP(I56,L:L,P:P)+100%)*D56 -> 24.897264 | I56: =I44+1 -> 2019
A57: 2019-08 | B57: 5.647 | C57: 6.2359836 | D57: 22.272242 | E57: =D57-C57 -> 16.036258 | F57: 9.918834 | H57: =(_xlfn.XLOOKUP(I57,L:L,P:P)+100%)*D57 -> 22.478691 | I57: =I45+1 -> 2019
A58: 2019-09 | B58: 4.973 | C58: 6.486976 | D58: 25.193591 | E58: =D58-C58 -> 18.706615 | F58: 5.453081 | H58: =(_xlfn.XLOOKUP(I58,L:L,P:P)+100%)*D58 -> 25.42712 | I58: =I46+1 -> 2019
A59: 2019-10 | B59: 5.532 | C59: 7.3670017 | D59: 31.867592 | E59: =D59-C59 -> 24.50059 | F59: 1.726854 | H59: =(_xlfn.XLOOKUP(I59,L:L,P:P)+100%)*D59 -> 32.162984 | I59: =I47+1 -> 2019
A60: 2019-11 | B60: 5.364688 | C60: 7.7770693 | D60: 40.803192 | E60: =D60-C60 -> 33.026123 | F60: -3.742252 | G60: 0.365975 | H60: =(_xlfn.XLOOKUP(I60,L:L,P:P)+100%)*D60 -> 41.181412 | I60: =I48+1 -> 2019
A61: 2019-12 | B61: 5.611 | C61: 7.2933426 | D61: 45.324968 | E61: =D61-C61 -> 38.031625 | F61: -6.644534 | H61: =(_xlfn.XLOOKUP(I61,L:L,P:P)+100%)*D61 -> 45.745102 | I61: =I49+1 -> 2019
A62: 2020-01 | B62: 5.712 | C62: 9.895615 | D62: 50.800794 | E62: =D62-C62 -> 40.905179 | H62: =(_xlfn.XLOOKUP(I62,L:L,P:P)+100%)*D62 -> 51.159447 | I62: =I50+1 -> 2020
A63: 2020-02 | B63: 4.95 | C63: 7.651694 | D63: 41.751593 | E63: =D63-C63 -> 34.099899 | H63: =(_xlfn.XLOOKUP(I63,L:L,P:P)+100%)*D63 -> 42.046359 | I63: =I51+1 -> 2020
...

Sheet UK
A1: Date | B1: Production(bcm) | C1: Electricity(bcm) | D1: Total(bcm) | E1: Non_power(bcm)
A2: 2015-01 | B2: 3.636 | C2: 1.674 | D2: 9.247 | E2: 7.573
A3: 2015-02 | B3: 3.145 | C3: 2.134 | D3: 8.421 | E3: 6.287
A4: 2015-03 | B4: 3.683 | C4: 1.506 | D4: 7.86 | E4: 6.354
A5: 2015-04 | B5: 3.399 | C5: 1.347 | D5: 5.546 | E5: 4.199
A6: 2015-05 | B6: 3.916 | C6: 1.412 | D6: 4.943 | E6: 3.531
A7: 2015-06 | B7: 3.353 | C7: 1.528 | D7: 4.206 | E7: 2.678
A8: 2015-07 | B8: 3.103 | C8: 1.525 | D8: 3.858 | E8: 2.333
A9: 2015-08 | B9: 3.063 | C9: 1.582 | D9: 3.846 | E9: 2.264
A10: 2015-09 | B10: 2.951 | C10: 1.918 | D10: 4.613 | E10: 2.695
A11: 2015-10 | B11: 3.529 | C11: 1.932 | D11: 5.693 | E11: 3.761
A12: 2015-11 | B12: 3.705 | C12: 1.879 | D12: 6.968 | E12: 5.089
A13: 2015-12 | B13: 3.828 | C13: 1.702 | D13: 6.973 | E13: 5.271
... A138: 2026-05 | B138: 2.268 | C138: 0.767 | D138: 3.61 | E138: 2.843

Sheet CH
A1: Date | B1: Imports | C1: Exports | D1: Net_imports
A2: 2015-01 | B2: 1.513 | C2: 1.017 | D2: 0.496
A3: 2015-02 | B3: 1.696 | C3: 1.202 | D3: 0.494
A4: 2015-03 | B4: 0.931 | C4: 0.558 | D4: 0.373
A5: 2015-04 | B5: 0.852 | C5: 0.591 | D5: 0.261
A6: 2015-05 | B6: 0.808 | C6: 0.63 | D6: 0.178
A7: 2015-06 | B7: 0.671 | C7: 0.551 | D7: 0.12
A8: 2015-07 | B8: 1.324 | C8: 1.227 | D8: 0.097
A9: 2015-08 | B9: 0.649 | C9: 0.54 | D9: 0.109
A10: 2015-09 | B10: 0.88 | C10: 0.712 | D10: 0.168
A11: 2015-10 | B11: 0.811 | C11: 0.522 | D11: 0.289
A12: 2015-11 | B12: 1.602 | C12: 1.242 | D12: 0.36
A13: 2015-12 | B13: 2.177 | C13: 1.741 | D13: 0.436
... A138: 2026-05 | B138: 0.506 | C138: 0.362 | D138: 0.144

Sheet RS
A1: Date | B1: Imports | C1: Exports | D1: Net_imports
A2: 2015-01 | B2: =B14 -> 0.307 | C2: =C14 -> 0 | D2: =D14 -> 0.307
A3: 2015-02 | B3: =B15 -> 0.257 | C3: =C15 -> 0 | D3: =D15 -> 0.257
A4: 2015-03 | B4: =B16 -> 0.21 | C4: =C16 -> 0 | D4: =D16 -> 0.21
A5: 2015-04 | B5: =B17 -> 0.157 | C5: =C17 -> 0 | D5: =D17 -> 0.157
A6: 2015-05 | B6: =B18 -> 0.172 | C6: =C18 -> 0 | D6: =D18 -> 0.172
A7: 2015-06 | B7: =B19 -> 0.158 | C7: =C19 -> 0 | D7: =D19 -> 0.158
A8: 2015-07 | B8: =B20 -> 0.165 | C8: =C20 -> 0 | D8: =D20 -> 0.165
A9: 2015-08 | B9: =B21 -> 0.147 | C9: =C21 -> 0 | D9: =D21 -> 0.147
A10: 2015-09 | B10: =B22 -> 0.145 | C10: =C22 -> 0 | D10: =D22 -> 0.145
A11: 2015-10 | B11: =B23 -> 0.174 | C11: =C23 -> 0 | D11: =D23 -> 0.174
A12: 2015-11 | B12: =B24 -> 0.264 | C12: =C24 -> 0 | D12: =D24 -> 0.264
A13: 2015-12 | B13: =B25 -> 0.291 | C13: =C25 -> 0 | D13: =D25 -> 0.291
... A25: 2016-12 | B25: =B37 -> 0.291 | C25: =C37 -> 0 | D25: =D37 -> 0.291
A26: 2017-01 | B26: 0.307 | C26: =E26/1000 -> 0 | D26: =B26-C26 -> 0.307
A27: 2017-02 | B27: 0.257 | C27: =E27/1000 -> 0 | D27: =B27-C27 -> 0.257
A28: 2017-03 | B28: 0.21 | C28: =E28/1000 -> 0 | D28: =B28-C28 -> 0.21
A29: 2017-04 | B29: 0.157 | C29: =E29/1000 -> 0 | D29: =B29-C29 -> 0.157
A30: 2017-05 | B30: 0.172 | C30: =E30/1000 -> 0 | D30: =B30-C30 -> 0.172
A31: 2017-06 | B31: 0.158 | C31: =E31/1000 -> 0 | D31: =B31-C31 -> 0.158
A32: 2017-07 | B32: 0.165 | C32: =E32/1000 -> 0 | D32: =B32-C32 -> 0.165
A33: 2017-08 | B33: 0.147 | C33: =E33/1000 -> 0 | D33: =B33-C33 -> 0.147
A34: 2017-09 | B34: 0.145 | C34: =E34/1000 -> 0 | D34: =B34-C34 -> 0.145
A35: 2017-10 | B35: 0.174 | C35: =E35/1000 -> 0 | D35: =B35-C35 -> 0.174
A36: 2017-11 | B36: 0.264 | C36: =E36/1000 -> 0 | D36: =B36-C36 -> 0.264
A37: 2017-12 | B37: 0.291 | C37: =E37/1000 -> 0 | D37: =B37-C37 -> 0.291
... A138: 2026-05 | B138: 0.867 | C138: =E138/1000 -> 0 | D138: =B138-C138 -> 0.867

Sheet CH+RS
A1: Date | B1: CH_RS_net_exports
A2: 2015-01 | B2: =CH!D2+RS!D2 -> 0.803
A3: 2015-02 | B3: =CH!D3+RS!D3 -> 0.751
A4: 2015-03 | B4: =CH!D4+RS!D4 -> 0.583
A5: 2015-04 | B5: =CH!D5+RS!D5 -> 0.418
A6: 2015-05 | B6: =CH!D6+RS!D6 -> 0.35
A7: 2015-06 | B7: =CH!D7+RS!D7 -> 0.278
A8: 2015-07 | B8: =CH!D8+RS!D8 -> 0.262
A9: 2015-08 | B9: =CH!D9+RS!D9 -> 0.256
A10: 2015-09 | B10: =CH!D10+RS!D10 -> 0.313
A11: 2015-10 | B11: =CH!D11+RS!D11 -> 0.463
A12: 2015-11 | B12: =CH!D12+RS!D12 -> 0.624
A13: 2015-12 | B13: =CH!D13+RS!D13 -> 0.727
... A138: 2026-05 | B138: =CH!D138+RS!D138 -> 1.011
